<?xml version="1.0" encoding="utf-8"?>
<!-- This URDF was automatically created by SolidWorks to URDF Exporter! Originally created by Stephen Brawner (brawner@gmail.com) 
     Commit Version: 1.6.0-4-g7f85cfe  Build Version: 1.6.7995.38578
     For more information, please see http://wiki.ros.org/sw_urdf_exporter -->
<robot
  name="Biped_Longfoot">
  <link
    name="Body">
    <inertial>
      <origin
        xyz="0.00875 -0.00011577 0.049281"
        rpy="0 0 0" />
      <mass
        value="0.5" />
      <inertia
        ixx="0.016664"
        ixy="-2.5808E-16"
        ixz="-2.5495E-05"
        iyy="0.01491"
        iyz="3.7322E-12"
        izz="0.025732" />
    </inertial>
    <visual>
      <origin
        xyz="0 0 0"
        rpy="0 0 0" />
      <geometry>
        <mesh
          filename="../meshes/Body.STL" />
      </geometry>
      <material
        name="">
        <color
          rgba="0.28627 0.66275 0.32941 1" />
      </material>
    </visual>
    <collision>
      <origin
        xyz="0 0 0"
        rpy="0 0 0" />
      <geometry>
        <mesh
          filename="../meshes/Body.STL" />
      </geometry>
    </collision>
  </link>
  <link
    name="L_Hip">
    <inertial>
      <origin
        xyz="-0.011702 0.019238 -1.7814E-08"
        rpy="0 0 0" />
      <mass
        value="0.24499" />
      <inertia
        ixx="0.00022957"
        ixy="-3.2972E-12"
        ixz="-2.2508E-10"
        iyy="0.00023971"
        iyz="-5.4613E-12"
        izz="0.00016193" />
    </inertial>
    <visual>
      <origin
        xyz="0 0 0"
        rpy="0 0 0" />
      <geometry>
        <mesh
          filename="../meshes/L_Hip.STL" />
      </geometry>
      <material
        name="">
        <color
          rgba="0.0078431 0.23922 0.82353 1" />
      </material>
    </visual>
    <collision>
      <origin
        xyz="0 0 0"
        rpy="0 0 0" />
      <geometry>
        <mesh
          filename="../meshes/L_Hip.STL" />
      </geometry>
    </collision>
  </link>
  <joint
    name="L_J1"
    type="revolute">
    <origin
      xyz="0.034433 0.1 0.05"
      rpy="0 0 0" />
    <parent
      link="Body" />
    <child
      link="L_Hip" />
    <axis
      xyz="1 0 0" />
    <limit
      lower="-0.35"
      upper="0.35"
      effort="2"
      velocity="0" />
  </joint>
  <link
    name="L_Thigh">
    <inertial>
      <origin
        xyz="-0.081737 -0.023332 1.0839E-06"
        rpy="0 0 0" />
      <mass
        value="0.21389" />
      <inertia
        ixx="0.00015693"
        ixy="-2.9003E-06"
        ixz="2.0598E-08"
        iyy="0.00028797"
        iyz="4.3352E-10"
        izz="0.00016039" />
    </inertial>
    <visual>
      <origin
        xyz="0 0 0"
        rpy="0 0 0" />
      <geometry>
        <mesh
          filename="../meshes/L_Thigh.STL" />
      </geometry>
      <material
        name="">
        <color
          rgba="0.0078431 0.23922 0.82353 1" />
      </material>
    </visual>
    <collision>
      <origin
        xyz="0 0 0"
        rpy="0 0 0" />
      <geometry>
        <mesh
          filename="../meshes/L_Thigh.STL" />
      </geometry>
    </collision>
  </link>
  <joint
    name="L_J2"
    type="revolute">
    <origin
      xyz="-0.02045 0.07 0"
      rpy="0 0 0" />
    <parent
      link="L_Hip" />
    <child
      link="L_Thigh" />
    <axis
      xyz="0 -1 0" />
    <limit
      lower="-2.8"
      upper="2.8"
      effort="2"
      velocity="0" />
  </joint>
  <link
    name="L_Shin">
    <inertial>
      <origin
        xyz="-0.14161 -0.0031964 -1.1056E-05"
        rpy="0 0 0" />
      <mass
        value="0.06737" />
      <inertia
        ixx="9.9237E-06"
        ixy="3.9964E-09"
        ixz="1.3799E-11"
        iyy="6.1692E-05"
        iyz="8.0018E-09"
        izz="6.2515E-05" />
    </inertial>
    <visual>
      <origin
        xyz="0 0 0"
        rpy="0 0 0" />
      <geometry>
        <mesh
          filename="../meshes/L_Shin.STL" />
      </geometry>
      <material
        name="">
        <color
          rgba="0.79216 0.81961 0.93333 1" />
      </material>
    </visual>
    <collision>
      <origin
        xyz="0 0 0"
        rpy="0 0 0" />
      <geometry>
        <mesh
          filename="../meshes/L_Shin.STL" />
      </geometry>
    </collision>
  </link>
  <joint
    name="L_J3"
    type="revolute">
    <origin
      xyz="-0.218 0 0"
      rpy="0 0 0" />
    <parent
      link="L_Thigh" />
    <child
      link="L_Shin" />
    <axis
      xyz="0 1 0" />
    <limit
      lower="-2.8"
      upper="2.8"
      effort="2"
      velocity="0" />
  </joint>
  <link
    name="R_Hip">
    <inertial>
      <origin
        xyz="-0.0117020911662147 -0.0192378662036612 1.78144100304589E-08"
        rpy="0 0 0" />
      <mass
        value="0.244991783639187" />
      <inertia
        ixx="0.000229565612565136"
        ixy="3.29715841194678E-12"
        ixz="2.2508006806926E-10"
        iyy="0.000239714320228986"
        iyz="-5.46133417321109E-12"
        izz="0.000161925907771084" />
    </inertial>
    <visual>
      <origin
        xyz="0 0 0"
        rpy="0 0 0" />
      <geometry>
        <mesh
          filename="../meshes/R_Hip.STL" />
      </geometry>
      <material
        name="">
        <color
          rgba="0.00784313725490196 0.23921568627451 0.823529411764706 1" />
      </material>
    </visual>
    <collision>
      <origin
        xyz="0 0 0"
        rpy="0 0 0" />
      <geometry>
        <mesh
          filename="../meshes/R_Hip.STL" />
      </geometry>
    </collision>
  </link>
  <joint
    name="R_J1"
    type="revolute">
    <origin
      xyz="0.034433 -0.1 0.05"
      rpy="0 0 0" />
    <parent
      link="Body" />
    <child
      link="R_Hip" />
    <axis
      xyz="1 0 0" />
    <limit
      lower="-0.35"
      upper="0.35"
      effort="2"
      velocity="0" />
  </joint>
  <link
    name="R_Thigh">
    <inertial>
      <origin
        xyz="-0.0817374624571683 0.0233317564196753 -1.083925488643E-06"
        rpy="0 0 0" />
      <mass
        value="0.213887019230149" />
      <inertia
        ixx="0.000156929203122604"
        ixy="2.90025887800606E-06"
        ixz="-2.05980738831229E-08"
        iyy="0.00028797163198921"
        iyz="4.33522037891126E-10"
        izz="0.000160390422080857" />
    </inertial>
    <visual>
      <origin
        xyz="0 0 0"
        rpy="0 0 0" />
      <geometry>
        <mesh
          filename="../meshes/R_Thigh.STL" />
      </geometry>
      <material
        name="">
        <color
          rgba="0.792156862745098 0.819607843137255 0.933333333333333 1" />
      </material>
    </visual>
    <collision>
      <origin
        xyz="0 0 0"
        rpy="0 0 0" />
      <geometry>
        <mesh
          filename="../meshes/R_Thigh.STL" />
      </geometry>
    </collision>
  </link>
  <joint
    name="R_J2"
    type="revolute">
    <origin
      xyz="-0.02045 -0.07 0"
      rpy="0 0 0" />
    <parent
      link="R_Hip" />
    <child
      link="R_Thigh" />
    <axis
      xyz="0 1 0" />
    <limit
      lower="-2.8"
      upper="2.8"
      effort="2"
      velocity="0" />
  </joint>
  <link
    name="R_Shin">
    <inertial>
      <origin
        xyz="-0.14161383520369 0.00319643914352419 1.1056228479342E-05"
        rpy="0 0 0" />
      <mass
        value="0.0673695809293491" />
      <inertia
        ixx="9.92372270760311E-06"
        ixy="-3.99640905795578E-09"
        ixz="-1.37986739148306E-11"
        iyy="6.1691663047134E-05"
        iyz="8.0017977631751E-09"
        izz="6.2514882356553E-05" />
    </inertial>
    <visual>
      <origin
        xyz="0 0 0"
        rpy="0 0 0" />
      <geometry>
        <mesh
          filename="../meshes/R_Shin.STL" />
      </geometry>
      <material
        name="">
        <color
          rgba="0.792156862745098 0.819607843137255 0.933333333333333 1" />
      </material>
    </visual>
    <collision>
      <origin
        xyz="0 0 0"
        rpy="0 0 0" />
      <geometry>
        <mesh
          filename="../meshes/R_Shin.STL" />
      </geometry>
    </collision>
  </link>
  <joint
    name="R_J3"
    type="revolute">
    <origin
      xyz="-0.218 0 0"
      rpy="0 0 0" />
    <parent
      link="R_Thigh" />
    <child
      link="R_Shin" />
    <axis
      xyz="0 -1 0" />
    <limit
      lower="-2.8"
      upper="2.8"
      effort="2"
      velocity="0" />
  </joint>
  <link
    name="ReactWheelX">
    <inertial>
      <origin
        xyz="0 2.7756E-17 0"
        rpy="0 0 0" />
      <mass
        value="0.097845" />
      <inertia
        ixx="0.00023479"
        ixy="-3.099E-21"
        ixz="5.7417E-23"
        iyy="0.0001185"
        iyz="1.8513E-20"
        izz="0.0001185" />
    </inertial>
    <visual>
      <origin
        xyz="0 0 0"
        rpy="0 0 0" />
      <geometry>
        <mesh
          filename="../meshes/ReactWheelX.STL" />
      </geometry>
      <material
        name="">
        <color
          rgba="0.79216 0.81961 0.93333 1" />
      </material>
    </visual>
    <collision>
      <origin
        xyz="0 0 0"
        rpy="0 0 0" />
      <geometry>
        <mesh
          filename="../meshes/ReactWheelX.STL" />
      </geometry>
    </collision>
  </link>
  <joint
    name="WheelX"
    type="continuous">
    <origin
      xyz="-0.07 0 0.05"
      rpy="0 0 0" />
    <parent
      link="Body" />
    <child
      link="ReactWheelX" />
    <axis
      xyz="1 0 0" />
  </joint>
  <link
    name="ReactWheelY">
    <inertial>
      <origin
        xyz="0 2.7756E-17 0"
        rpy="0 0 0" />
      <mass
        value="0.097845" />
      <inertia
        ixx="0.0001185"
        ixy="-4.9506E-21"
        ixz="-3.4276E-20"
        iyy="0.00023479"
        iyz="1.5587E-21"
        izz="0.0001185" />
    </inertial>
    <visual>
      <origin
        xyz="0 0 0"
        rpy="0 0 0" />
      <geometry>
        <mesh
          filename="../meshes/ReactWheelY.STL" />
      </geometry>
      <material
        name="">
        <color
          rgba="0.79216 0.81961 0.93333 1" />
      </material>
    </visual>
    <collision>
      <origin
        xyz="0 0 0"
        rpy="0 0 0" />
      <geometry>
        <mesh
          filename="../meshes/ReactWheelY.STL" />
      </geometry>
    </collision>
  </link>
  <joint
    name="WheelY"
    type="continuous">
    <origin
      xyz="0.020147 0 0.05"
      rpy="0 0 0" />
    <parent
      link="Body" />
    <child
      link="ReactWheelY" />
    <axis
      xyz="0 1 0" />
  </joint>
</robot>