<?xml version="1.0" encoding="utf-8"?>
<!-- This URDF was automatically created by SolidWorks to URDF Exporter! Originally created by Stephen Brawner (brawner@gmail.com) 
     Commit Version: 1.6.0-4-g7f85cfe  Build Version: 1.6.7995.38578
     For more information, please see http://wiki.ros.org/sw_urdf_exporter -->
<robot
  name="JumpRig2">
  <link
    name="Base">
    <inertial>
      <origin
        xyz="6.88005327532887E-17 -2.77555756156289E-17 0.467576600112633"
        rpy="0 0 0" />
      <mass
        value="1.16451700934069" />
      <inertia
        ixx="0.0621888932681032"
        ixy="2.57690828241955E-11"
        ixz="1.05249017371805E-17"
        iyy="0.0624630869986235"
        iyz="1.69194831214046E-19"
        izz="0.000535285144268021" />
    </inertial>
    <visual>
      <origin
        xyz="0 0 0"
        rpy="0 0 0" />
      <geometry>
        <mesh
          filename="package://JumpRig2/meshes/Base.STL" />
      </geometry>
      <material
        name="">
        <color
          rgba="0.792156862745098 0.819607843137255 0.933333333333333 1" />
      </material>
    </visual>
    <collision>
      <origin
        xyz="0 0 0"
        rpy="0 0 0" />
      <geometry>
        <mesh
          filename="package://JumpRig2/meshes/Base.STL" />
      </geometry>
    </collision>
  </link>
  <link
    name="Carriage">
    <inertial>
      <origin
        xyz="0.0213430057397923 -8.80728414490162E-05 4.22726344689872E-06"
        rpy="0 0 0" />
      <mass
        value="0.438107006723366" />
      <inertia
        ixx="0.000312571171497994"
        ixy="-4.61173576570612E-08"
        ixz="1.67100703649424E-08"
        iyy="0.000297689456127191"
        iyz="1.44352336736831E-08"
        izz="0.000220369025063559" />
    </inertial>
    <visual>
      <origin
        xyz="0 0 0"
        rpy="0 0 0" />
      <geometry>
        <mesh
          filename="package://JumpRig2/meshes/Carriage.STL" />
      </geometry>
      <material
        name="">
        <color
          rgba="0.792156862745098 0.819607843137255 0.933333333333333 1" />
      </material>
    </visual>
    <collision>
      <origin
        xyz="0 0 0"
        rpy="0 0 0" />
      <geometry>
        <mesh
          filename="package://JumpRig2/meshes/Carriage.STL" />
      </geometry>
    </collision>
  </link>
  <joint
    name="Prismatic1"
    type="prismatic">
    <origin
      xyz="0 0 0.316"
      rpy="0 0 0" />
    <parent
      link="Base" />
    <child
      link="Carriage" />
    <axis
      xyz="0 0 -1" />
    <limit
      lower="0"
      upper="10"
      effort="0"
      velocity="0" />
  </joint>
  <link
    name="Hip">
    <inertial>
      <origin
        xyz="0.124 0.001531695043768 3.49720252756924E-15"
        rpy="0 0 0" />
      <mass
        value="0.108085294122534" />
      <inertia
        ixx="9.72938154450631E-05"
        ixy="-3.64224167319349E-20"
        ixz="6.97742127919856E-10"
        iyy="0.000194016724988732"
        iyz="-2.30363020784611E-19"
        izz="0.000104918580327439" />
    </inertial>
    <visual>
      <origin
        xyz="0 0 0"
        rpy="0 0 0" />
      <geometry>
        <mesh
          filename="package://JumpRig2/meshes/Hip.STL" />
      </geometry>
      <material
        name="">
        <color
          rgba="0.00784313725490196 0.23921568627451 0.823529411764706 1" />
      </material>
    </visual>
    <collision>
      <origin
        xyz="0 0 0"
        rpy="0 0 0" />
      <geometry>
        <mesh
          filename="package://JumpRig2/meshes/Hip.STL" />
      </geometry>
    </collision>
  </link>
  <joint
    name="Revolute1"
    type="revolute">
    <origin
      xyz="0.061 0.0118 0"
      rpy="0 0 0" />
    <parent
      link="Carriage" />
    <child
      link="Hip" />
    <axis
      xyz="0 -1 0" />
    <limit
      lower="-1.5708"
      upper="1.5708"
      effort="3"
      velocity="50" />
  </joint>
  <link
    name="Knee">
    <inertial>
      <origin
        xyz="0.0302806604519978 -0.0124187217877956 -0.0018409537496803"
        rpy="0 0 0" />
      <mass
        value="0.267605307693932" />
      <inertia
        ixx="0.000263522276391332"
        ixy="4.61331602367225E-08"
        ixz="1.40899007952966E-08"
        iyy="0.000252903443935366"
        iyz="-1.40474886753592E-08"
        izz="0.000144511810899968" />
    </inertial>
    <visual>
      <origin
        xyz="0 0 0"
        rpy="0 0 0" />
      <geometry>
        <mesh
          filename="package://JumpRig2/meshes/Knee.STL" />
      </geometry>
      <material
        name="">
        <color
          rgba="0.286274509803922 0.662745098039216 0.329411764705882 1" />
      </material>
    </visual>
    <collision>
      <origin
        xyz="0 0 0"
        rpy="0 0 0" />
      <geometry>
        <mesh
          filename="package://JumpRig2/meshes/Knee.STL" />
      </geometry>
    </collision>
  </link>
  <joint
    name="Revolute2"
    type="revolute">
    <origin
      xyz="0.248 0 0"
      rpy="0 0 0" />
    <parent
      link="Hip" />
    <child
      link="Knee" />
    <axis
      xyz="0 -1 0" />
    <limit
      lower="-1.5708"
      upper="1.5708"
      effort="3"
      velocity="50" />
  </joint>
  <link
    name="Foot">
    <inertial>
      <origin
        xyz="0 0 0.00214861159675591"
        rpy="0 0 0" />
      <mass
        value="0.0290279405926851" />
      <inertia
        ixx="4.29116424476198E-06"
        ixy="-8.10704700027522E-25"
        ixz="1.53441230322681E-23"
        iyy="4.29116424476198E-06"
        iyz="1.44116962942334E-22"
        izz="5.04314017877839E-06" />
    </inertial>
    <visual>
      <origin
        xyz="0 0 0"
        rpy="0 0 0" />
      <geometry>
        <mesh
          filename="package://JumpRig2/meshes/Foot.STL" />
      </geometry>
      <material
        name="">
        <color
          rgba="0.286274509803922 0.662745098039216 0.329411764705882 1" />
      </material>
    </visual>
    <collision>
      <origin
        xyz="0 0 0"
        rpy="0 0 0" />
      <geometry>
        <mesh
          filename="package://JumpRig2/meshes/Foot.STL" />
      </geometry>
    </collision>
  </link>
  <joint
    name="Fixed1"
    type="fixed">
    <origin
      xyz="0.061 -0.0123 -0.3"
      rpy="0 0 0" />
    <parent
      link="Knee" />
    <child
      link="Foot" />
    <axis
      xyz="0 0 0" />
  </joint>
</robot>