<?xml version="1.0" encoding="utf-8"?>
<!-- This URDF was automatically created by SolidWorks to URDF Exporter! Originally created by Stephen Brawner (brawner@gmail.com) 
     Commit Version: 1.6.0-4-g7f85cfe  Build Version: 1.6.7995.38578
     For more information, please see http://wiki.ros.org/sw_urdf_exporter -->
<robot
  name="JumpRig2">
  <link
    name="Base">
    <inertial>
      <origin
        xyz="6.83432580784625E-17 0 0.467576600112633"
        rpy="0 0 0" />
      <mass
        value="1.16451700934069" />
      <inertia
        ixx="0.0621888932681032"
        ixy="2.57690828202237E-11"
        ixz="1.045454385454E-17"
        iyy="0.0624630869986236"
        iyz="2.40133840546594E-19"
        izz="0.000535285144268021" />
    </inertial>
    <visual>
      <origin
        xyz="0 0 0"
        rpy="0 0 0" />
      <geometry>
        <mesh
          filename="package://JumpRig2/meshes/Base.STL" />
      </geometry>
      <material
        name="">
        <color
          rgba="0.792156862745098 0.819607843137255 0.933333333333333 1" />
      </material>
    </visual>
    <collision>
      <origin
        xyz="0 0 0"
        rpy="0 0 0" />
      <geometry>
        <mesh
          filename="package://JumpRig2/meshes/Base.STL" />
      </geometry>
    </collision>
  </link>
  <link
    name="Carriage">
    <inertial>
      <origin
        xyz="0.0213430057397923 -8.80728414490162E-05 4.22726344689872E-06"
        rpy="0 0 0" />
      <mass
        value="0.438107006723366" />
      <inertia
        ixx="0.000312571171497994"
        ixy="-4.61173576570583E-08"
        ixz="1.67100703649391E-08"
        iyy="0.000297689456127191"
        iyz="1.44352336736798E-08"
        izz="0.000220369025063559" />
    </inertial>
    <visual>
      <origin
        xyz="0 0 0"
        rpy="0 0 0" />
      <geometry>
        <mesh
          filename="package://JumpRig2/meshes/Carriage.STL" />
      </geometry>
      <material
        name="">
        <color
          rgba="0.792156862745098 0.819607843137255 0.933333333333333 1" />
      </material>
    </visual>
    <collision>
      <origin
        xyz="0 0 0"
        rpy="0 0 0" />
      <geometry>
        <mesh
          filename="package://JumpRig2/meshes/Carriage.STL" />
      </geometry>
    </collision>
  </link>
  <joint
    name="Prismatic1"
    type="prismatic">
    <origin
      xyz="0 0 0.316"
      rpy="0 0 0" />
    <parent
      link="Base" />
    <child
      link="Carriage" />
    <axis
      xyz="0 0 1" />
    <limit
      lower="-0.15"
      upper="0.6"
      effort="0"
      velocity="0" />
  </joint>
  <link
    name="Hip">
    <inertial>
      <origin
        xyz="0.124 0.00153169504376797 3.49720252756924E-15"
        rpy="0 0 0" />
      <mass
        value="0.108085294122534" />
      <inertia
        ixx="9.72938154450631E-05"
        ixy="-3.85399991000707E-20"
        ixz="6.97742127922253E-10"
        iyy="0.000194016724988732"
        iyz="-2.28001849074156E-19"
        izz="0.000104918580327439" />
    </inertial>
    <visual>
      <origin
        xyz="0 0 0"
        rpy="0 0 0" />
      <geometry>
        <mesh
          filename="package://JumpRig2/meshes/Hip.STL" />
      </geometry>
      <material
        name="">
        <color
          rgba="0.00784313725490196 0.23921568627451 0.823529411764706 1" />
      </material>
    </visual>
    <collision>
      <origin
        xyz="0 0 0"
        rpy="0 0 0" />
      <geometry>
        <mesh
          filename="package://JumpRig2/meshes/Hip.STL" />
      </geometry>
    </collision>
  </link>
  <joint
    name="Revolute1"
    type="revolute">
    <origin
      xyz="0.061 0.0118 0"
      rpy="0 0 0" />
    <parent
      link="Carriage" />
    <child
      link="Hip" />
    <axis
      xyz="0 1 0" />
    <limit
      lower="-1.5708"
      upper="1.5708"
      effort="3"
      velocity="50" />
  </joint>
  <link
    name="Knee">
    <inertial>
      <origin
        xyz="0.0111478770556511 -0.0124927736903426 -1.13579919615026E-05"
        rpy="0 0 0" />
      <mass
        value="0.164807658641037" />
      <inertia
        ixx="0.000116392865034867"
        ixy="4.6133160236708E-08"
        ixz="1.65944863559037E-08"
        iyy="0.000146682342457415"
        iyz="-1.40474886752533E-08"
        izz="9.80702857193393E-05" />
    </inertial>
    <visual>
      <origin
        xyz="0 0 0"
        rpy="0 0 0" />
      <geometry>
        <mesh
          filename="package://JumpRig2/meshes/Knee.STL" />
      </geometry>
      <material
        name="">
        <color
          rgba="0.286274509803922 0.662745098039216 0.329411764705882 1" />
      </material>
    </visual>
    <collision>
      <origin
        xyz="0 0 0"
        rpy="0 0 0" />
      <geometry>
        <mesh
          filename="package://JumpRig2/meshes/Knee.STL" />
      </geometry>
    </collision>
  </link>
  <joint
    name="Revolute2"
    type="revolute">
    <origin
      xyz="0.248 0 0"
      rpy="0 0 0" />
    <parent
      link="Hip" />
    <child
      link="Knee" />
    <axis
      xyz="0 1 0" />
    <limit
      lower="-1.5708"
      upper="1.5708"
      effort="3"
      velocity="50" />
  </joint>
  <link
    name="Shin">
    <inertial>
      <origin
        xyz="-4.52019204422727E-05 7.7715611723761E-16 -0.00477420558829328"
        rpy="0 0 0" />
      <mass
        value="0.102797649052896" />
      <inertia
        ixx="0.000147129411356465"
        ixy="1.43929101649689E-20"
        ixz="-2.50458556060759E-09"
        iyy="0.000106221101477951"
        iyz="-1.08487636847628E-19"
        izz="4.64415251806284E-05" />
    </inertial>
    <visual>
      <origin
        xyz="0 0 0"
        rpy="0 0 0" />
      <geometry>
        <mesh
          filename="package://JumpRig2/meshes/Shin.STL" />
      </geometry>
      <material
        name="">
        <color
          rgba="0.792156862745098 0.819607843137255 0.933333333333333 1" />
      </material>
    </visual>
    <collision>
      <origin
        xyz="0 0 0"
        rpy="0 0 0" />
      <geometry>
        <mesh
          filename="package://JumpRig2/meshes/Shin.STL" />
      </geometry>
    </collision>
  </link>
  <joint
    name="Fixed1"
    type="fixed">
    <origin
      xyz="0.061 -0.0123 0"
      rpy="0 0 0" />
    <parent
      link="Knee" />
    <child
      link="Shin" />
    <axis
      xyz="0 0 0" />
  </joint>
  <link
    name="Foot">
    <inertial>
      <origin
        xyz="0 0 0.00214861159675591"
        rpy="0 0 0" />
      <mass
        value="0.0290279405926851" />
      <inertia
        ixx="4.29116424476198E-06"
        ixy="-8.10704700027522E-25"
        ixz="1.53441230322681E-23"
        iyy="4.29116424476198E-06"
        iyz="1.44116962942334E-22"
        izz="5.04314017877839E-06" />
    </inertial>
    <visual>
      <origin
        xyz="0 0 0"
        rpy="0 0 0" />
      <geometry>
        <mesh
          filename="package://JumpRig2/meshes/Foot.STL" />
      </geometry>
      <material
        name="">
        <color
          rgba="0.286274509803922 0.662745098039216 0.329411764705882 1" />
      </material>
    </visual>
    <collision>
      <origin
        xyz="0 0 0"
        rpy="0 0 0" />
      <geometry>
        <mesh
          filename="package://JumpRig2/meshes/Foot.STL" />
      </geometry>
    </collision>
  </link>
  <joint
    name="Fixed2"
    type="fixed">
    <origin
      xyz="0 0 -0.300000000000001"
      rpy="0 0 0" />
    <parent
      link="Shin" />
    <child
      link="Foot" />
    <axis
      xyz="0 0 0" />
  </joint>
</robot>