<?xml version="1.0" encoding="utf-8"?>
<!-- This URDF was automatically created by SolidWorks to URDF Exporter! Originally created by Stephen Brawner (brawner@gmail.com) 
     Commit Version: 1.6.0-4-g7f85cfe  Build Version: 1.6.7995.38578
     For more information, please see http://wiki.ros.org/sw_urdf_exporter -->
<robot
  name="Jumpy">
  <link
    name="GuidePole">
    <inertial>
      <origin
        xyz="1.7347E-18 0.5 0"
        rpy="0 0 0" />
      <mass
        value="0.07854" />
      <inertia
        ixx="0.0065455"
        ixy="3.5293E-21"
        ixz="-1.034E-23"
        iyy="9.8175E-07"
        iyz="-8.8233E-22"
        izz="0.0065455" />
    </inertial>
    <visual>
      <origin
        xyz="0 0 0"
        rpy="0 0 0" />
      <geometry>
        <mesh
          filename="../meshes/GuidePole.STL" />
      </geometry>
      <material
        name="">
        <color
          rgba="0.79216 0.81961 0.93333 1" />
      </material>
    </visual>
    <collision>
      <origin
        xyz="0 0 0"
        rpy="0 0 0" />
      <geometry>
        <mesh
          filename="../meshes/GuidePole.STL" />
      </geometry>
    </collision>
  </link>
  <link
    name="Hip">
    <inertial>
      <origin
        xyz="2.5386E-08 7.9774E-09 0.036439"
        rpy="0 0 0" />
      <mass
        value="0.19494" />
      <inertia
        ixx="9.7189E-05"
        ixy="-1.2257E-10"
        ixz="4.0533E-12"
        iyy="9.4081E-05"
        iyz="2.9941E-12"
        izz="0.00017187" />
    </inertial>
    <visual>
      <origin
        xyz="0 0 0"
        rpy="0 0 0" />
      <geometry>
        <mesh
          filename="../meshes/Hip.STL" />
      </geometry>
      <material
        name="">
        <color
          rgba="0.28627 0.66275 0.32941 1" />
      </material>
    </visual>
    <collision>
      <origin
        xyz="0 0 0"
        rpy="0 0 0" />
      <geometry>
        <mesh
          filename="../meshes/Hip.STL" />
      </geometry>
    </collision>
  </link>
  <joint
    name="Prismatic1"
    type="prismatic">
    <origin
      xyz="0 0.5 0"
      rpy="0 0 0" />
    <parent
      link="GuidePole" />
    <child
      link="Hip" />
    <axis
      xyz="0 -1 0" />
    <limit
      lower="-0.5"
      upper="1.5"
      effort="0"
      velocity="0" />
  </joint>
  <link
    name="Thigh">
    <inertial>
      <origin
        xyz="5.1837E-07 -0.11253 -0.021305"
        rpy="0 0 0" />
      <mass
        value="0.24897" />
      <inertia
        ixx="0.00019947"
        ixy="1.9838E-08"
        ixz="1.1756E-10"
        iyy="0.0001936"
        iyz="-2.9018E-06"
        izz="0.00036259" />
    </inertial>
    <visual>
      <origin
        xyz="0 0 0"
        rpy="0 0 0" />
      <geometry>../meshes/
        <mesh
          filename="../meshes/Thigh.STL" />
      </geometry>
      <material
        name="">
        <color
          rgba="0.0078431 0.23922 0.82353 1" />
      </material>
    </visual>
    <collision>
      <origin
        xyz="0 0 0"
        rpy="0 0 0" />
      <geometry>
        <mesh
          filename="../meshes/Thigh.STL" />
      </geometry>
    </collision>
  </link>
  <joint
    name="Rotation1"
    type="continuous">
    <origin
      xyz="0 0 0.081567"
      rpy="0 0 1.5708" />
    <parent
      link="Hip" />
    <child
      link="Thigh" />
    <axis
      xyz="0 0 -1" />
    <limit
      effort="1"
      velocity="0" />
  </joint>
  <link
    name="Shin">
    <inertial>
      <origin
        xyz="0.11082 2.2923E-05 -0.009413"
        rpy="0 0 0" />
      <mass
        value="0.068723" />
      <inertia
        ixx="1.5542E-05"
        ixy="-6.4688E-11"
        ixz="8.5674E-09"
        iyy="6.9995E-05"
        iyz="-1.1864E-08"
        izz="6.422E-05" />
    </inertial>
    <visual>
      <origin
        xyz="0 0 0"
        rpy="0 0 0" />
      <geometry>
        <mesh
          filename="../meshes/Shin.STL" />
      </geometry>
      <material
        name="">
        <color
          rgba="0.79216 0.81961 0.93333 1" />
      </material>
    </visual>
    <collision>
      <origin
        xyz="0 0 0"
        rpy="0 0 0" />
      <geometry>
        <mesh
          filename="../meshes/Shin.STL" />
      </geometry>
    </collision>
  </link>
  <joint
    name="Rotation2"
    type="continuous">
    <origin
      xyz="0 -0.318 0"
      rpy="0 0 -1.5708" />
    <parent
      link="Thigh" />
    <child
      link="Shin" />
    <axis
      xyz="0 0 1" />
    <limit
      effort="1"
      velocity="0" />
  </joint>
</robot>