<?xml version="1.0" encoding="utf-8"?>
<!-- This URDF was automatically created by SolidWorks to URDF Exporter! Originally created by Stephen Brawner (brawner@gmail.com) 
     Commit Version: 1.6.0-4-g7f85cfe  Build Version: 1.6.7995.38578
     For more information, please see http://wiki.ros.org/sw_urdf_exporter -->
<robot
  name="Quad">
  <link
    name="Body">
    <inertial>
      <origin
        xyz="-0.000343100031390819 0.0500000000000052 -0.000554626065973486"
        rpy="0 0 0" />
      <mass
        value="7.93838617368297" />
      <inertia
        ixx="0.0620908658837973"
        ixy="7.70262290866679E-19"
        ixz="1.33751530157446E-18"
        iyy="0.0972905110147254"
        iyz="4.95790430571969E-16"
        izz="0.0467432752751615" />
    </inertial>
    <visual>
      <origin
        xyz="0 0 0"
        rpy="0 0 0" />
      <geometry>
        <mesh
          filename="package://Quad/meshes/Body.STL" />
      </geometry>
      <material
        name="">
        <color
          rgba="0.286274509803922 0.662745098039216 0.329411764705882 1" />
      </material>
    </visual>
    <collision>
      <origin
        xyz="0 0 0"
        rpy="0 0 0" />
      <geometry>
        <mesh
          filename="package://Quad/meshes/Body.STL" />
      </geometry>
    </collision>
  </link>
  <link
    name="FR_Hip">
    <inertial>
      <origin
        xyz="-0.0192378662036614 -1.78144099194366E-08 0.0297489009840163"
        rpy="0 0 0" />
      <mass
        value="0.244991783639187" />
      <inertia
        ixx="0.000239714320228986"
        ixy="5.46133418531262E-12"
        ixz="-3.29715836420577E-12"
        iyy="0.000161925907771085"
        iyz="2.25080068115558E-10"
        izz="0.000229565612565136" />
    </inertial>
    <visual>
      <origin
        xyz="0 0 0"
        rpy="0 0 0" />
      <geometry>
        <mesh
          filename="package://Quad/meshes/FR_Hip.STL" />
      </geometry>
      <material
        name="">
        <color
          rgba="0.00784313725490196 0.23921568627451 0.823529411764706 1" />
      </material>
    </visual>
    <collision>
      <origin
        xyz="0 0 0"
        rpy="0 0 0" />
      <geometry>
        <mesh
          filename="package://Quad/meshes/FR_Hip.STL" />
      </geometry>
    </collision>
  </link>
  <joint
    name="FR_J1"
    type="continuous">
    <origin
      xyz="-0.1 0.05 0.20557"
      rpy="0 0 0" />
    <parent
      link="Body" />
    <child
      link="FR_Hip" />
    <axis
      xyz="0 0 -1" />
  </joint>
  <link
    name="FR_Thigh">
    <inertial>
      <origin
        xyz="0.0213045756655137 5.18368892268861E-07 0.112532577948084"
        rpy="0 0 0" />
      <mass
        value="0.248973034603068" />
      <inertia
        ixx="0.000362587337502919"
        ixy="-1.17555629130147E-10"
        ixz="-2.90184454491023E-06"
        iyy="0.000199472018852034"
        iyz="-1.98376638240301E-08"
        izz="0.00019359900881669" />
    </inertial>
    <visual>
      <origin
        xyz="0 0 0"
        rpy="0 0 0" />
      <geometry>
        <mesh
          filename="package://Quad/meshes/FR_Thigh.STL" />
      </geometry>
      <material
        name="">
        <color
          rgba="0.00784313725490196 0.23921568627451 0.823529411764706 1" />
      </material>
    </visual>
    <collision>
      <origin
        xyz="0 0 0"
        rpy="0 0 0" />
      <geometry>
        <mesh
          filename="package://Quad/meshes/FR_Thigh.STL" />
      </geometry>
    </collision>
  </link>
  <joint
    name="FR_J2"
    type="continuous">
    <origin
      xyz="-0.0700000000000002 0 0.045979703345944"
      rpy="0 0 0" />
    <parent
      link="FR_Hip" />
    <child
      link="FR_Thigh" />
    <axis
      xyz="1 0 0" />
  </joint>
  <link
    name="FR_Shin">
    <inertial>
      <origin
        xyz="0.00941299977249632 1.65527585011399E-05 0.110857092842009"
        rpy="0 0 0" />
      <mass
        value="0.0687228409087856" />
      <inertia
        ixx="6.42198625809037E-05"
        ixy="8.56742150772803E-09"
        ixz="1.18644635684177E-08"
        iyy="6.99945188679625E-05"
        iyz="6.46876985471922E-11"
        izz="1.55422946691621E-05" />
    </inertial>
    <visual>
      <origin
        xyz="0 0 0"
        rpy="0 0 0" />
      <geometry>
        <mesh
          filename="package://Quad/meshes/FR_Shin.STL" />
      </geometry>
      <material
        name="">
        <color
          rgba="0.792156862745098 0.819607843137255 0.933333333333333 1" />
      </material>
    </visual>
    <collision>
      <origin
        xyz="0 0 0"
        rpy="0 0 0" />
      <geometry>
        <mesh
          filename="package://Quad/meshes/FR_Shin.STL" />
      </geometry>
    </collision>
  </link>
  <joint
    name="FR_J3"
    type="continuous">
    <origin
      xyz="0 0 0.318"
      rpy="0 0 0" />
    <parent
      link="FR_Thigh" />
    <child
      link="FR_Shin" />
    <axis
      xyz="-1 0 0" />
  </joint>
  <link
    name="FL_Hip">
    <inertial>
      <origin
        xyz="0.0192378662036614 1.78144099749478E-08 0.0297489009840162"
        rpy="0 0 0" />
      <mass
        value="0.244991783639187" />
      <inertia
        ixx="0.000239714320228986"
        ixy="5.46133416847529E-12"
        ixz="3.29715838172874E-12"
        iyy="0.000161925907771085"
        iyz="-2.25080068065572E-10"
        izz="0.000229565612565136" />
    </inertial>
    <visual>
      <origin
        xyz="0 0 0"
        rpy="0 0 0" />
      <geometry>
        <mesh
          filename="package://Quad/meshes/FL_Hip.STL" />
      </geometry>
      <material
        name="">
        <color
          rgba="0.00784313725490196 0.23921568627451 0.823529411764706 1" />
      </material>
    </visual>
    <collision>
      <origin
        xyz="0 0 0"
        rpy="0 0 0" />
      <geometry>
        <mesh
          filename="package://Quad/meshes/FL_Hip.STL" />
      </geometry>
    </collision>
  </link>
  <joint
    name="FL_J1"
    type="continuous">
    <origin
      xyz="0.1 0.05 0.20557"
      rpy="0 0 0" />
    <parent
      link="Body" />
    <child
      link="FL_Hip" />
    <axis
      xyz="0 0 -1" />
  </joint>
  <link
    name="FL_Thigh">
    <inertial>
      <origin
        xyz="-0.0218666576877501 -6.56602355014746E-07 0.143513864617987"
        rpy="0 0 0" />
      <mass
        value="0.179307876346527" />
      <inertia
        ixx="0.000261542342004721"
        ixy="-1.23286169225086E-10"
        ixz="2.17188845277569E-06"
        iyy="0.000148769435505943"
        iyz="1.94860718514575E-08"
        izz="0.000138988786643352" />
    </inertial>
    <visual>
      <origin
        xyz="0 0 0"
        rpy="0 0 0" />
      <geometry>
        <mesh
          filename="package://Quad/meshes/FL_Thigh.STL" />
      </geometry>
      <material
        name="">
        <color
          rgba="0.792156862745098 0.819607843137255 0.933333333333333 1" />
      </material>
    </visual>
    <collision>
      <origin
        xyz="0 0 0"
        rpy="0 0 0" />
      <geometry>
        <mesh
          filename="package://Quad/meshes/FL_Thigh.STL" />
      </geometry>
    </collision>
  </link>
  <joint
    name="FL_J2"
    type="continuous">
    <origin
      xyz="0.0700000000000002 0 0.045979703345944"
      rpy="0 0 0" />
    <parent
      link="FL_Hip" />
    <child
      link="FL_Thigh" />
    <axis
      xyz="-1 0 0" />
  </joint>
  <link
    name="FL_Shin">
    <inertial>
      <origin
        xyz="-0.00941299977249624 -1.65527585011815E-05 0.110857092842009"
        rpy="0 0 0" />
      <mass
        value="0.0687228409087855" />
      <inertia
        ixx="6.42198625809037E-05"
        ixy="8.56742150772561E-09"
        ixz="-1.18644635684158E-08"
        iyy="6.99945188679625E-05"
        iyz="-6.46876985454777E-11"
        izz="1.55422946691621E-05" />
    </inertial>
    <visual>
      <origin
        xyz="0 0 0"
        rpy="0 0 0" />
      <geometry>
        <mesh
          filename="package://Quad/meshes/FL_Shin.STL" />
      </geometry>
      <material
        name="">
        <color
          rgba="0.792156862745098 0.819607843137255 0.933333333333333 1" />
      </material>
    </visual>
    <collision>
      <origin
        xyz="0 0 0"
        rpy="0 0 0" />
      <geometry>
        <mesh
          filename="package://Quad/meshes/FL_Shin.STL" />
      </geometry>
    </collision>
  </link>
  <joint
    name="FL_J3"
    type="continuous">
    <origin
      xyz="0 0 0.318"
      rpy="0 0 0" />
    <parent
      link="FL_Thigh" />
    <child
      link="FL_Shin" />
    <axis
      xyz="1 0 0" />
  </joint>
  <link
    name="BR_Hip">
    <inertial>
      <origin
        xyz="-0.0192378662036616 1.78144099749478E-08 -0.0297489009840163"
        rpy="0 0 0" />
      <mass
        value="0.244991783639187" />
      <inertia
        ixx="0.000239714320228986"
        ixy="-5.46133414739369E-12"
        ixz="3.29715837674072E-12"
        iyy="0.000161925907771085"
        iyz="2.25080068062643E-10"
        izz="0.000229565612565136" />
    </inertial>
    <visual>
      <origin
        xyz="0 0 0"
        rpy="0 0 0" />
      <geometry>
        <mesh
          filename="package://Quad/meshes/BR_Hip.STL" />
      </geometry>
      <material
        name="">
        <color
          rgba="0.00784313725490196 0.23921568627451 0.823529411764706 1" />
      </material>
    </visual>
    <collision>
      <origin
        xyz="0 0 0"
        rpy="0 0 0" />
      <geometry>
        <mesh
          filename="package://Quad/meshes/BR_Hip.STL" />
      </geometry>
    </collision>
  </link>
  <joint
    name="BR_J1"
    type="continuous">
    <origin
      xyz="-0.1 0.05 -0.20557"
      rpy="0 0 0" />
    <parent
      link="Body" />
    <child
      link="BR_Hip" />
    <axis
      xyz="0 0 1" />
  </joint>
  <link
    name="BR_Thigh">
    <inertial>
      <origin
        xyz="0.0218666576877501 -6.56602354931479E-07 -0.143513864617987"
        rpy="0 0 0" />
      <mass
        value="0.179307876346527" />
      <inertia
        ixx="0.000261542342004721"
        ixy="1.23286169286076E-10"
        ixz="2.17188845277567E-06"
        iyy="0.000148769435505943"
        iyz="-1.94860718513925E-08"
        izz="0.000138988786643352" />
    </inertial>
    <visual>
      <origin
        xyz="0 0 0"
        rpy="0 0 0" />
      <geometry>
        <mesh
          filename="package://Quad/meshes/BR_Thigh.STL" />
      </geometry>
      <material
        name="">
        <color
          rgba="0.792156862745098 0.819607843137255 0.933333333333333 1" />
      </material>
    </visual>
    <collision>
      <origin
        xyz="0 0 0"
        rpy="0 0 0" />
      <geometry>
        <mesh
          filename="package://Quad/meshes/BR_Thigh.STL" />
      </geometry>
    </collision>
  </link>
  <joint
    name="BR_J2"
    type="continuous">
    <origin
      xyz="-0.0700000000000003 0 -0.045979703345944"
      rpy="0 0 0" />
    <parent
      link="BR_Hip" />
    <child
      link="BR_Thigh" />
    <axis
      xyz="1 0 0" />
  </joint>
  <link
    name="BR_Shin">
    <inertial>
      <origin
        xyz="0.00941299977249627 -1.65527585011815E-05 -0.110857092842009"
        rpy="0 0 0" />
      <mass
        value="0.0687228409087856" />
      <inertia
        ixx="6.42198625809038E-05"
        ixy="-8.56742150772778E-09"
        ixz="-1.18644635684186E-08"
        iyy="6.99945188679626E-05"
        iyz="6.46876985473799E-11"
        izz="1.55422946691621E-05" />
    </inertial>
    <visual>
      <origin
        xyz="0 0 0"
        rpy="0 0 0" />
      <geometry>
        <mesh
          filename="package://Quad/meshes/BR_Shin.STL" />
      </geometry>
      <material
        name="">
        <color
          rgba="0.792156862745098 0.819607843137255 0.933333333333333 1" />
      </material>
    </visual>
    <collision>
      <origin
        xyz="0 0 0"
        rpy="0 0 0" />
      <geometry>
        <mesh
          filename="package://Quad/meshes/BR_Shin.STL" />
      </geometry>
    </collision>
  </link>
  <joint
    name="BR_J3"
    type="continuous">
    <origin
      xyz="0 0 -0.318"
      rpy="0 0 0" />
    <parent
      link="BR_Thigh" />
    <child
      link="BR_Shin" />
    <axis
      xyz="-1 0 0" />
  </joint>
  <link
    name="BL_Hip">
    <inertial>
      <origin
        xyz="0.0192378662036614 -1.78144099888256E-08 -0.0297489009840163"
        rpy="0 0 0" />
      <mass
        value="0.244991783639187" />
      <inertia
        ixx="0.000239714320228986"
        ixy="-5.46133416099501E-12"
        ixz="-3.29715835994939E-12"
        iyy="0.000161925907771085"
        iyz="-2.25080068073951E-10"
        izz="0.000229565612565136" />
    </inertial>
    <visual>
      <origin
        xyz="0 0 0"
        rpy="0 0 0" />
      <geometry>
        <mesh
          filename="package://Quad/meshes/BL_Hip.STL" />
      </geometry>
      <material
        name="">
        <color
          rgba="0.00784313725490196 0.23921568627451 0.823529411764706 1" />
      </material>
    </visual>
    <collision>
      <origin
        xyz="0 0 0"
        rpy="0 0 0" />
      <geometry>
        <mesh
          filename="package://Quad/meshes/BL_Hip.STL" />
      </geometry>
    </collision>
  </link>
  <joint
    name="BL_J1"
    type="continuous">
    <origin
      xyz="0.1 0.05 -0.20557"
      rpy="0 0 0" />
    <parent
      link="Body" />
    <child
      link="BL_Hip" />
    <axis
      xyz="0 0 1" />
  </joint>
  <link
    name="BL_Thigh">
    <inertial>
      <origin
        xyz="-0.0213045756655136 5.1836889221335E-07 -0.112532577948083"
        rpy="0 0 0" />
      <mass
        value="0.248973034603069" />
      <inertia
        ixx="0.00036258733750292"
        ixy="1.17555629151155E-10"
        ixz="-2.90184454491026E-06"
        iyy="0.000199472018852034"
        iyz="1.98376638237415E-08"
        izz="0.000193599008816691" />
    </inertial>
    <visual>
      <origin
        xyz="0 0 0"
        rpy="0 0 0" />
      <geometry>
        <mesh
          filename="package://Quad/meshes/BL_Thigh.STL" />
      </geometry>
      <material
        name="">
        <color
          rgba="0.00784313725490196 0.23921568627451 0.823529411764706 1" />
      </material>
    </visual>
    <collision>
      <origin
        xyz="0 0 0"
        rpy="0 0 0" />
      <geometry>
        <mesh
          filename="package://Quad/meshes/BL_Thigh.STL" />
      </geometry>
    </collision>
  </link>
  <joint
    name="BL_J2"
    type="continuous">
    <origin
      xyz="0.0700000000000002 0 -0.045979703345944"
      rpy="0 0 0" />
    <parent
      link="BL_Hip" />
    <child
      link="BL_Thigh" />
    <axis
      xyz="-1 0 0" />
  </joint>
  <link
    name="BL_Shin">
    <inertial>
      <origin
        xyz="-0.00941299977249625 1.65527585011677E-05 -0.110857092842009"
        rpy="0 0 0" />
      <mass
        value="0.0687228409087855" />
      <inertia
        ixx="6.42198625809038E-05"
        ixy="-8.56742150772904E-09"
        ixz="1.1864463568417E-08"
        iyy="6.99945188679626E-05"
        iyz="-6.46876985468449E-11"
        izz="1.55422946691621E-05" />
    </inertial>
    <visual>
      <origin
        xyz="0 0 0"
        rpy="0 0 0" />
      <geometry>
        <mesh
          filename="package://Quad/meshes/BL_Shin.STL" />
      </geometry>
      <material
        name="">
        <color
          rgba="0.286274509803922 0.662745098039216 0.329411764705882 1" />
      </material>
    </visual>
    <collision>
      <origin
        xyz="0 0 0"
        rpy="0 0 0" />
      <geometry>
        <mesh
          filename="package://Quad/meshes/BL_Shin.STL" />
      </geometry>
    </collision>
  </link>
  <joint
    name="BL_J3"
    type="continuous">
    <origin
      xyz="0 0 -0.318"
      rpy="0 0 0" />
    <parent
      link="BL_Thigh" />
    <child
      link="BL_Shin" />
    <axis
      xyz="1 0 0" />
  </joint>
</robot>