<?xml version="1.0" encoding="utf-8"?>
<!-- This URDF was automatically created by SolidWorks to URDF Exporter! Originally created by Stephen Brawner (brawner@gmail.com) 
     Commit Version: 1.6.0-4-g7f85cfe  Build Version: 1.6.7995.38578
     For more information, please see http://wiki.ros.org/sw_urdf_exporter -->
<robot
  name="Quad">
  <link
    name="Body">
    <inertial>
      <origin
        xyz="-0.000343100031391042 0.0500000000000052 -0.000554626065973528"
        rpy="0 0 0" />
      <mass
        value="7.93838617368297" />
      <inertia
        ixx="0.0620908658837973"
        ixy="7.83444715829776E-19"
        ixz="1.33742316748413E-18"
        iyy="0.0972905110147254"
        iyz="4.95790873023931E-16"
        izz="0.0467432752751615" />
    </inertial>
    <visual>
      <origin
        xyz="0 0 0"
        rpy="0 0 0" />
      <geometry>
        <mesh
          filename="package://Quad/meshes/Body.STL" />
      </geometry>
      <material
        name="">
        <color
          rgba="0.286274509803922 0.662745098039216 0.329411764705882 1" />
      </material>
    </visual>
    <collision>
      <origin
        xyz="0 0 0"
        rpy="0 0 0" />
      <geometry>
        <mesh
          filename="package://Quad/meshes/Body.STL" />
      </geometry>
    </collision>
  </link>
  <link
    name="FR_Hip">
    <inertial>
      <origin
        xyz="-1.78144099055588E-08 0.0192378662036614 0.0297489009840162"
        rpy="0 0 0" />
      <mass
        value="0.244991783639187" />
      <inertia
        ixx="0.000161925907771085"
        ixy="-5.46133419282423E-12"
        ixz="2.25080068120081E-10"
        iyy="0.000239714320228986"
        iyz="3.29715836623352E-12"
        izz="0.000229565612565136" />
    </inertial>
    <visual>
      <origin
        xyz="0 0 0"
        rpy="0 0 0" />
      <geometry>
        <mesh
          filename="package://Quad/meshes/FR_Hip.STL" />
      </geometry>
      <material
        name="">
        <color
          rgba="0.00784313725490196 0.23921568627451 0.823529411764706 1" />
      </material>
    </visual>
    <collision>
      <origin
        xyz="0 0 0"
        rpy="0 0 0" />
      <geometry>
        <mesh
          filename="package://Quad/meshes/FR_Hip.STL" />
      </geometry>
    </collision>
  </link>
  <joint
    name="FR_J1"
    type="continuous">
    <origin
      xyz="-0.1 0.05 0.20557"
      rpy="0 0 1.5708" />
    <parent
      link="Body" />
    <child
      link="FR_Hip" />
    <axis
      xyz="0 0 -1" />
  </joint>
  <link
    name="FR_Thigh">
    <inertial>
      <origin
        xyz="0.112532577948083 5.18368892032939E-07 -0.0213045756655136"
        rpy="0 0 0" />
      <mass
        value="0.248973034603068" />
      <inertia
        ixx="0.00019359900881669"
        ixy="-1.98376638240309E-08"
        ixz="2.90184454491022E-06"
        iyy="0.000199472018852034"
        iyz="1.17555629130432E-10"
        izz="0.000362587337502919" />
    </inertial>
    <visual>
      <origin
        xyz="0 0 0"
        rpy="0 0 0" />
      <geometry>
        <mesh
          filename="package://Quad/meshes/FR_Thigh.STL" />
      </geometry>
      <material
        name="">
        <color
          rgba="0.00784313725490196 0.23921568627451 0.823529411764706 1" />
      </material>
    </visual>
    <collision>
      <origin
        xyz="0 0 0"
        rpy="0 0 0" />
      <geometry>
        <mesh
          filename="package://Quad/meshes/FR_Thigh.STL" />
      </geometry>
    </collision>
  </link>
  <joint
    name="FR_J2"
    type="continuous">
    <origin
      xyz="0 0.07 0.04598"
      rpy="1.5708 -1.5708 0" />
    <parent
      link="FR_Hip" />
    <child
      link="FR_Thigh" />
    <axis
      xyz="0 0 -1" />
  </joint>
  <link
    name="FR_Shin">
    <inertial>
      <origin
        xyz="0.110857092842009 1.65527585011399E-05 -0.00941299977249632"
        rpy="0 0 0" />
      <mass
        value="0.0687228409087856" />
      <inertia
        ixx="1.55422946691621E-05"
        ixy="6.4687698547195E-11"
        ixz="-1.18644635684177E-08"
        iyy="6.99945188679625E-05"
        iyz="-8.56742150772803E-09"
        izz="6.42198625809037E-05" />
    </inertial>
    <visual>
      <origin
        xyz="0 0 0"
        rpy="0 0 0" />
      <geometry>
        <mesh
          filename="package://Quad/meshes/FR_Shin.STL" />
      </geometry>
      <material
        name="">
        <color
          rgba="0.792156862745098 0.819607843137255 0.933333333333333 1" />
      </material>
    </visual>
    <collision>
      <origin
        xyz="0 0 0"
        rpy="0 0 0" />
      <geometry>
        <mesh
          filename="package://Quad/meshes/FR_Shin.STL" />
      </geometry>
    </collision>
  </link>
  <joint
    name="FR_J3"
    type="continuous">
    <origin
      xyz="0.318 0 0"
      rpy="0 0 0" />
    <parent
      link="FR_Thigh" />
    <child
      link="FR_Shin" />
    <axis
      xyz="0 0 1" />
  </joint>
  <link
    name="FL_Hip">
    <inertial>
      <origin
        xyz="-1.78144100027033E-08 0.0192378662036614 0.0297489009840162"
        rpy="0 0 0" />
      <mass
        value="0.244991783639187" />
      <inertia
        ixx="0.000161925907771085"
        ixy="-5.46133415030393E-12"
        ixz="2.25080068071265E-10"
        iyy="0.000239714320228986"
        iyz="3.29715838363704E-12"
        izz="0.000229565612565136" />
    </inertial>
    <visual>
      <origin
        xyz="0 0 0"
        rpy="0 0 0" />
      <geometry>
        <mesh
          filename="package://Quad/meshes/FL_Hip.STL" />
      </geometry>
      <material
        name="">
        <color
          rgba="0.00784313725490196 0.23921568627451 0.823529411764706 1" />
      </material>
    </visual>
    <collision>
      <origin
        xyz="0 0 0"
        rpy="0 0 0" />
      <geometry>
        <mesh
          filename="package://Quad/meshes/FL_Hip.STL" />
      </geometry>
    </collision>
  </link>
  <joint
    name="FL_J1"
    type="fixed">
    <origin
      xyz="0.1 0.05 0.20557"
      rpy="0 0 -1.5708" />
    <parent
      link="Body" />
    <child
      link="FL_Hip" />
    <axis
      xyz="0 0 0" />
  </joint>
  <link
    name="FL_Thigh">
    <inertial>
      <origin
        xyz="0.143513864617987 6.56602354806579E-07 -0.0218666576877501"
        rpy="0 0 0" />
      <mass
        value="0.179307876346527" />
      <inertia
        ixx="0.000138988786643352"
        ixy="-1.9486071851457E-08"
        ixz="2.17188845277572E-06"
        iyy="0.000148769435505943"
        iyz="1.23286169250186E-10"
        izz="0.000261542342004721" />
    </inertial>
    <visual>
      <origin
        xyz="0 0 0"
        rpy="0 0 0" />
      <geometry>
        <mesh
          filename="package://Quad/meshes/FL_Thigh.STL" />
      </geometry>
      <material
        name="">
        <color
          rgba="0.792156862745098 0.819607843137255 0.933333333333333 1" />
      </material>
    </visual>
    <collision>
      <origin
        xyz="0 0 0"
        rpy="0 0 0" />
      <geometry>
        <mesh
          filename="package://Quad/meshes/FL_Thigh.STL" />
      </geometry>
    </collision>
  </link>
  <joint
    name="FL_J2"
    type="continuous">
    <origin
      xyz="0 0.0700000000000001 0.045979703345944"
      rpy="1.5707963267949 -1.5707963267949 0" />
    <parent
      link="FL_Hip" />
    <child
      link="FL_Thigh" />
    <axis
      xyz="0 0 -1" />
  </joint>
  <link
    name="FL_Shin">
    <inertial>
      <origin
        xyz="0.110857092842009 1.65527585011954E-05 -0.00941299977249624"
        rpy="0 0 0" />
      <mass
        value="0.0687228409087855" />
      <inertia
        ixx="1.55422946691621E-05"
        ixy="6.46876985410522E-11"
        ixz="-1.18644635684046E-08"
        iyy="6.99945188679625E-05"
        iyz="-8.56742150772693E-09"
        izz="6.42198625809037E-05" />
    </inertial>
    <visual>
      <origin
        xyz="0 0 0"
        rpy="0 0 0" />
      <geometry>
        <mesh
          filename="package://Quad/meshes/FL_Shin.STL" />
      </geometry>
      <material
        name="">
        <color
          rgba="0.792156862745098 0.819607843137255 0.933333333333333 1" />
      </material>
    </visual>
    <collision>
      <origin
        xyz="0 0 0"
        rpy="0 0 0" />
      <geometry>
        <mesh
          filename="package://Quad/meshes/FL_Shin.STL" />
      </geometry>
    </collision>
  </link>
  <joint
    name="FL_J3"
    type="continuous">
    <origin
      xyz="0.318 0 0"
      rpy="0 0 0" />
    <parent
      link="FL_Thigh" />
    <child
      link="FL_Shin" />
    <axis
      xyz="0 0 1" />
  </joint>
  <link
    name="BR_Hip">
    <inertial>
      <origin
        xyz="-1.78144099888256E-08 0.0192378662036615 0.0297489009840163"
        rpy="0 0 0" />
      <mass
        value="0.244991783639187" />
      <inertia
        ixx="0.000161925907771085"
        ixy="-5.46133416507976E-12"
        ixz="2.25080068067916E-10"
        iyy="0.000239714320228986"
        iyz="3.29715837928489E-12"
        izz="0.000229565612565136" />
    </inertial>
    <visual>
      <origin
        xyz="0 0 0"
        rpy="0 0 0" />
      <geometry>
        <mesh
          filename="package://Quad/meshes/BR_Hip.STL" />
      </geometry>
      <material
        name="">
        <color
          rgba="0.00784313725490196 0.23921568627451 0.823529411764706 1" />
      </material>
    </visual>
    <collision>
      <origin
        xyz="0 0 0"
        rpy="0 0 0" />
      <geometry>
        <mesh
          filename="package://Quad/meshes/BR_Hip.STL" />
      </geometry>
    </collision>
  </link>
  <joint
    name="BR_J1"
    type="continuous">
    <origin
      xyz="-0.1 0.05 -0.20557"
      rpy="3.1416 0 -1.5708" />
    <parent
      link="Body" />
    <child
      link="BR_Hip" />
    <axis
      xyz="0 0 -1" />
  </joint>
  <link
    name="BR_Thigh">
    <inertial>
      <origin
        xyz="0.143513864617987 6.56602354695557E-07 -0.02186665768775"
        rpy="0 0 0" />
      <mass
        value="0.179307876346527" />
      <inertia
        ixx="0.000138988786643352"
        ixy="-1.94860718513956E-08"
        ixz="2.1718884527757E-06"
        iyy="0.000148769435505943"
        iyz="1.23286169261101E-10"
        izz="0.000261542342004721" />
    </inertial>
    <visual>
      <origin
        xyz="0 0 0"
        rpy="0 0 0" />
      <geometry>
        <mesh
          filename="package://Quad/meshes/BR_Thigh.STL" />
      </geometry>
      <material
        name="">
        <color
          rgba="0.792156862745098 0.819607843137255 0.933333333333333 1" />
      </material>
    </visual>
    <collision>
      <origin
        xyz="0 0 0"
        rpy="0 0 0" />
      <geometry>
        <mesh
          filename="package://Quad/meshes/BR_Thigh.STL" />
      </geometry>
    </collision>
  </link>
  <joint
    name="BR_J2"
    type="continuous">
    <origin
      xyz="0 0.0700000000000001 0.045979703345944"
      rpy="1.5707963267949 -1.5707963267949 0" />
    <parent
      link="BR_Hip" />
    <child
      link="BR_Thigh" />
    <axis
      xyz="0 0 -1" />
  </joint>
  <link
    name="BR_Shin">
    <inertial>
      <origin
        xyz="0.110857092842009 1.65527585011815E-05 -0.00941299977249621"
        rpy="0 0 0" />
      <mass
        value="0.0687228409087856" />
      <inertia
        ixx="1.55422946691621E-05"
        ixy="6.46876985429719E-11"
        ixz="-1.18644635684075E-08"
        iyy="6.99945188679626E-05"
        iyz="-8.56742150772646E-09"
        izz="6.42198625809038E-05" />
    </inertial>
    <visual>
      <origin
        xyz="0 0 0"
        rpy="0 0 0" />
      <geometry>
        <mesh
          filename="package://Quad/meshes/BR_Shin.STL" />
      </geometry>
      <material
        name="">
        <color
          rgba="0.792156862745098 0.819607843137255 0.933333333333333 1" />
      </material>
    </visual>
    <collision>
      <origin
        xyz="0 0 0"
        rpy="0 0 0" />
      <geometry>
        <mesh
          filename="package://Quad/meshes/BR_Shin.STL" />
      </geometry>
    </collision>
  </link>
  <joint
    name="BR_J3"
    type="continuous">
    <origin
      xyz="0.318 0 0"
      rpy="0 0 0" />
    <parent
      link="BR_Thigh" />
    <child
      link="BR_Shin" />
    <axis
      xyz="0 0 1" />
  </joint>
  <link
    name="BL_Hip">
    <inertial>
      <origin
        xyz="-1.78144099888256E-08 0.0192378662036613 0.0297489009840164"
        rpy="0 0 0" />
      <mass
        value="0.244991783639187" />
      <inertia
        ixx="0.000161925907771085"
        ixy="-5.46133416965868E-12"
        ixz="2.2508006807948E-10"
        iyy="0.000239714320228986"
        iyz="3.29715836187104E-12"
        izz="0.000229565612565136" />
    </inertial>
    <visual>
      <origin
        xyz="0 0 0"
        rpy="0 0 0" />
      <geometry>
        <mesh
          filename="package://Quad/meshes/BL_Hip.STL" />
      </geometry>
      <material
        name="">
        <color
          rgba="0.00784313725490196 0.23921568627451 0.823529411764706 1" />
      </material>
    </visual>
    <collision>
      <origin
        xyz="0 0 0"
        rpy="0 0 0" />
      <geometry>
        <mesh
          filename="package://Quad/meshes/BL_Hip.STL" />
      </geometry>
    </collision>
  </link>
  <joint
    name="BL_J1"
    type="continuous">
    <origin
      xyz="0.1 0.05 -0.205567"
      rpy="3.14159265358979 0 1.5707963267949" />
    <parent
      link="Body" />
    <child
      link="BL_Hip" />
    <axis
      xyz="0 0 -1" />
  </joint>
  <link
    name="BL_Thigh">
    <inertial>
      <origin
        xyz="0.112532577948084 5.18368891991305E-07 -0.0213045756655136"
        rpy="0 0 0" />
      <mass
        value="0.248973034603069" />
      <inertia
        ixx="0.000193599008816691"
        ixy="-1.98376638237407E-08"
        ixz="2.9018445449103E-06"
        iyy="0.000199472018852034"
        iyz="1.17555629134047E-10"
        izz="0.00036258733750292" />
    </inertial>
    <visual>
      <origin
        xyz="0 0 0"
        rpy="0 0 0" />
      <geometry>
        <mesh
          filename="package://Quad/meshes/BL_Thigh.STL" />
      </geometry>
      <material
        name="">
        <color
          rgba="0.00784313725490196 0.23921568627451 0.823529411764706 1" />
      </material>
    </visual>
    <collision>
      <origin
        xyz="0 0 0"
        rpy="0 0 0" />
      <geometry>
        <mesh
          filename="package://Quad/meshes/BL_Thigh.STL" />
      </geometry>
    </collision>
  </link>
  <joint
    name="BL_J2"
    type="continuous">
    <origin
      xyz="0 0.0700000000000002 0.045979703345944"
      rpy="1.5707963267949 -1.5707963267949 0" />
    <parent
      link="BL_Hip" />
    <child
      link="BL_Thigh" />
    <axis
      xyz="0 0 -1" />
  </joint>
  <link
    name="BL_Shin">
    <inertial>
      <origin
        xyz="0.110857092842009 1.65527585011399E-05 -0.00941299977249625"
        rpy="0 0 0" />
      <mass
        value="0.0687228409087855" />
      <inertia
        ixx="1.55422946691621E-05"
        ixy="6.46876985424367E-11"
        ixz="-1.18644635684059E-08"
        iyy="6.99945188679626E-05"
        iyz="-8.56742150772843E-09"
        izz="6.42198625809038E-05" />
    </inertial>
    <visual>
      <origin
        xyz="0 0 0"
        rpy="0 0 0" />
      <geometry>
        <mesh
          filename="package://Quad/meshes/BL_Shin.STL" />
      </geometry>
      <material
        name="">
        <color
          rgba="0.286274509803922 0.662745098039216 0.329411764705882 1" />
      </material>
    </visual>
    <collision>
      <origin
        xyz="0 0 0"
        rpy="0 0 0" />
      <geometry>
        <mesh
          filename="package://Quad/meshes/BL_Shin.STL" />
      </geometry>
    </collision>
  </link>
  <joint
    name="BL_J3"
    type="continuous">
    <origin
      xyz="0.318 0 0"
      rpy="0 0 0" />
    <parent
      link="BL_Thigh" />
    <child
      link="BL_Shin" />
    <axis
      xyz="0 0 1" />
  </joint>
</robot>