<?xml version="1.0" encoding="utf-8"?>
<!-- This URDF was automatically created by SolidWorks to URDF Exporter! Originally created by Stephen Brawner (brawner@gmail.com) 
     Commit Version: 1.6.0-4-g7f85cfe  Build Version: 1.6.7995.38578
     For more information, please see http://wiki.ros.org/sw_urdf_exporter -->
<robot
  name="Quad">
  <link
    name="Body">
    <inertial>
      <origin
        xyz="1.66533453693773E-16 0.05 -6.93889390390723E-18"
        rpy="0 0 0" />
      <mass
        value="7.96562277913682" />
      <inertia
        ixx="0.0621031423895584"
        ixy="-2.15450575540481E-18"
        ixz="6.91148814322294E-19"
        iyy="0.0973027875204873"
        iyz="-1.30905912806315E-18"
        izz="0.0467648433365861" />
    </inertial>
    <visual>
      <origin
        xyz="0 0 0"
        rpy="0 0 0" />
      <geometry>
        <mesh
          filename="package://Quad/meshes/Body.STL" />
      </geometry>
      <material
        name="">
        <color
          rgba="0.286274509803922 0.662745098039216 0.329411764705882 1" />
      </material>
    </visual>
    <collision>
      <origin
        xyz="0 0 0"
        rpy="0 0 0" />
      <geometry>
        <mesh
          filename="package://Quad/meshes/Body.STL" />
      </geometry>
    </collision>
  </link>
  <link
    name="FR_Hip">
    <inertial>
      <origin
        xyz="-0.0192378662036616 -1.78144099333144E-08 0.0297489009840163"
        rpy="0 0 0" />
      <mass
        value="0.244991783639187" />
      <inertia
        ixx="0.000239714320228986"
        ixy="5.4613341854408E-12"
        ixz="-3.29715836424991E-12"
        iyy="0.000161925907771085"
        iyz="2.25080068115034E-10"
        izz="0.000229565612565136" />
    </inertial>
    <visual>
      <origin
        xyz="0 0 0"
        rpy="0 0 0" />
      <geometry>
        <mesh
          filename="package://Quad/meshes/FR_Hip.STL" />
      </geometry>
      <material
        name="">
        <color
          rgba="0.00784313725490196 0.23921568627451 0.823529411764706 1" />
      </material>
    </visual>
    <collision>
      <origin
        xyz="0 0 0"
        rpy="0 0 0" />
      <geometry>
        <mesh
          filename="package://Quad/meshes/FR_Hip.STL" />
      </geometry>
    </collision>
  </link>
  <joint
    name="FR_J1"
    type="continuous">
    <origin
      xyz="-0.1 0.05 0.205567"
      rpy="0 0 0" />
    <parent
      link="Body" />
    <child
      link="FR_Hip" />
    <axis
      xyz="0 0 -1" />
  </joint>
  <link
    name="FR_Thigh">
    <inertial>
      <origin
        xyz="0.0213045756655138 5.18368892241106E-07 0.112532577948084"
        rpy="0 0 0" />
      <mass
        value="0.248973034603068" />
      <inertia
        ixx="0.000362587337502919"
        ixy="-1.17555629130347E-10"
        ixz="-2.90184454491023E-06"
        iyy="0.000199472018852034"
        iyz="-1.98376638240325E-08"
        izz="0.00019359900881669" />
    </inertial>
    <visual>
      <origin
        xyz="0 0 0"
        rpy="0 0 0" />
      <geometry>
        <mesh
          filename="package://Quad/meshes/FR_Thigh.STL" />
      </geometry>
      <material
        name="">
        <color
          rgba="0.00784313725490196 0.23921568627451 0.823529411764706 1" />
      </material>
    </visual>
    <collision>
      <origin
        xyz="0 0 0"
        rpy="0 0 0" />
      <geometry>
        <mesh
          filename="package://Quad/meshes/FR_Thigh.STL" />
      </geometry>
    </collision>
  </link>
  <joint
    name="FR_J2"
    type="continuous">
    <origin
      xyz="-0.0700000000000002 0 0.045979703345944"
      rpy="0 0 0" />
    <parent
      link="FR_Hip" />
    <child
      link="FR_Thigh" />
    <axis
      xyz="1 0 0" />
  </joint>
  <link
    name="FR_Shin">
    <inertial>
      <origin
        xyz="0.00941299977249632 1.65527585011399E-05 0.110857092842009"
        rpy="0 0 0" />
      <mass
        value="0.0687228409087856" />
      <inertia
        ixx="6.42198625809037E-05"
        ixy="8.56742150772815E-09"
        ixz="1.18644635684178E-08"
        iyy="6.99945188679625E-05"
        iyz="6.46876985469214E-11"
        izz="1.55422946691621E-05" />
    </inertial>
    <visual>
      <origin
        xyz="0 0 0"
        rpy="0 0 0" />
      <geometry>
        <mesh
          filename="package://Quad/meshes/FR_Shin.STL" />
      </geometry>
      <material
        name="">
        <color
          rgba="0.792156862745098 0.819607843137255 0.933333333333333 1" />
      </material>
    </visual>
    <collision>
      <origin
        xyz="0 0 0"
        rpy="0 0 0" />
      <geometry>
        <mesh
          filename="package://Quad/meshes/FR_Shin.STL" />
      </geometry>
    </collision>
  </link>
  <joint
    name="FR_J3"
    type="continuous">
    <origin
      xyz="0 0 0.318"
      rpy="0 0 0" />
    <parent
      link="FR_Thigh" />
    <child
      link="FR_Shin" />
    <axis
      xyz="-1 0 0" />
  </joint>
  <link
    name="FL_Hip">
    <inertial>
      <origin
        xyz="0.0192378662036614 1.78144100027033E-08 0.0297489009840162"
        rpy="0 0 0" />
      <mass
        value="0.244991783639187" />
      <inertia
        ixx="0.000239714320228986"
        ixy="5.46133416810985E-12"
        ixz="3.29715838173479E-12"
        iyy="0.000161925907771085"
        iyz="-2.25080068066873E-10"
        izz="0.000229565612565136" />
    </inertial>
    <visual>
      <origin
        xyz="0 0 0"
        rpy="0 0 0" />
      <geometry>
        <mesh
          filename="package://Quad/meshes/FL_Hip.STL" />
      </geometry>
      <material
        name="">
        <color
          rgba="0.00784313725490196 0.23921568627451 0.823529411764706 1" />
      </material>
    </visual>
    <collision>
      <origin
        xyz="0 0 0"
        rpy="0 0 0" />
      <geometry>
        <mesh
          filename="package://Quad/meshes/FL_Hip.STL" />
      </geometry>
    </collision>
  </link>
  <joint
    name="FL_J1"
    type="continuous">
    <origin
      xyz="0.1 0.05 0.205567"
      rpy="0 0 0" />
    <parent
      link="Body" />
    <child
      link="FL_Hip" />
    <axis
      xyz="0 0 -1" />
  </joint>
  <link
    name="FL_Thigh">
    <inertial>
      <origin
        xyz="-0.0189308933438334 -5.55471749624781E-07 0.112857002495052"
        rpy="0 0 0" />
      <mass
        value="0.232342826148228" />
      <inertia
        ixx="0.000352781899754072"
        ixy="-1.17555629065877E-10"
        ixz="2.90184454491025E-06"
        iyy="0.000194519426806648"
        iyz="1.98376638239619E-08"
        izz="0.000188646416771304" />
    </inertial>
    <visual>
      <origin
        xyz="0 0 0"
        rpy="0 0 0" />
      <geometry>
        <mesh
          filename="package://Quad/meshes/FL_Thigh.STL" />
      </geometry>
      <material
        name="">
        <color
          rgba="0.792156862745098 0.819607843137255 0.933333333333333 1" />
      </material>
    </visual>
    <collision>
      <origin
        xyz="0 0 0"
        rpy="0 0 0" />
      <geometry>
        <mesh
          filename="package://Quad/meshes/FL_Thigh.STL" />
      </geometry>
    </collision>
  </link>
  <joint
    name="FL_J2"
    type="continuous">
    <origin
      xyz="0.0700000000000002 0 0.045979703345944"
      rpy="0 0 0" />
    <parent
      link="FL_Hip" />
    <child
      link="FL_Thigh" />
    <axis
      xyz="-1 0 0" />
  </joint>
  <link
    name="FL_Shin">
    <inertial>
      <origin
        xyz="-0.00941299977249622 -1.65527585011815E-05 0.110857092842009"
        rpy="0 0 0" />
      <mass
        value="0.0687228409087855" />
      <inertia
        ixx="6.42198625809037E-05"
        ixy="8.56742150772585E-09"
        ixz="-1.18644635684156E-08"
        iyy="6.99945188679625E-05"
        iyz="-6.46876985450502E-11"
        izz="1.55422946691621E-05" />
    </inertial>
    <visual>
      <origin
        xyz="0 0 0"
        rpy="0 0 0" />
      <geometry>
        <mesh
          filename="package://Quad/meshes/FL_Shin.STL" />
      </geometry>
      <material
        name="">
        <color
          rgba="0.792156862745098 0.819607843137255 0.933333333333333 1" />
      </material>
    </visual>
    <collision>
      <origin
        xyz="0 0 0"
        rpy="0 0 0" />
      <geometry>
        <mesh
          filename="package://Quad/meshes/FL_Shin.STL" />
      </geometry>
    </collision>
  </link>
  <joint
    name="FL_J3"
    type="continuous">
    <origin
      xyz="0 0 0.318"
      rpy="0 0 0" />
    <parent
      link="FL_Thigh" />
    <child
      link="FL_Shin" />
    <axis
      xyz="1 0 0" />
  </joint>
  <link
    name="BR_Hip">
    <inertial>
      <origin
        xyz="-0.0192378662036615 1.78144099749478E-08 -0.0297489009840162"
        rpy="0 0 0" />
      <mass
        value="0.244991783639187" />
      <inertia
        ixx="0.000239714320228986"
        ixy="-5.46133414281198E-12"
        ixz="3.29715837632147E-12"
        iyy="0.000161925907771085"
        iyz="2.25080068063195E-10"
        izz="0.000229565612565136" />
    </inertial>
    <visual>
      <origin
        xyz="0 0 0"
        rpy="0 0 0" />
      <geometry>
        <mesh
          filename="package://Quad/meshes/BR_Hip.STL" />
      </geometry>
      <material
        name="">
        <color
          rgba="0.00784313725490196 0.23921568627451 0.823529411764706 1" />
      </material>
    </visual>
    <collision>
      <origin
        xyz="0 0 0"
        rpy="0 0 0" />
      <geometry>
        <mesh
          filename="package://Quad/meshes/BR_Hip.STL" />
      </geometry>
    </collision>
  </link>
  <joint
    name="BR_J1"
    type="continuous">
    <origin
      xyz="-0.1 0.0500000000000001 -0.205567"
      rpy="0 0 0" />
    <parent
      link="Body" />
    <child
      link="BR_Hip" />
    <axis
      xyz="0 0 1" />
  </joint>
  <link
    name="BR_Thigh">
    <inertial>
      <origin
        xyz="0.0189308933438334 -5.55471749555392E-07 -0.112857002495052"
        rpy="0 0 0" />
      <mass
        value="0.232342826148228" />
      <inertia
        ixx="0.000352781899754072"
        ixy="1.17555629149808E-10"
        ixz="2.9018445449102E-06"
        iyy="0.000194519426806648"
        iyz="-1.98376638238709E-08"
        izz="0.000188646416771305" />
    </inertial>
    <visual>
      <origin
        xyz="0 0 0"
        rpy="0 0 0" />
      <geometry>
        <mesh
          filename="package://Quad/meshes/BR_Thigh.STL" />
      </geometry>
      <material
        name="">
        <color
          rgba="0.792156862745098 0.819607843137255 0.933333333333333 1" />
      </material>
    </visual>
    <collision>
      <origin
        xyz="0 0 0"
        rpy="0 0 0" />
      <geometry>
        <mesh
          filename="package://Quad/meshes/BR_Thigh.STL" />
      </geometry>
    </collision>
  </link>
  <joint
    name="BR_J2"
    type="continuous">
    <origin
      xyz="-0.0700000000000003 0 -0.045979703345944"
      rpy="0 0 0" />
    <parent
      link="BR_Hip" />
    <child
      link="BR_Thigh" />
    <axis
      xyz="1 0 0" />
  </joint>
  <link
    name="BR_Shin">
    <inertial>
      <origin
        xyz="0.00941299977249627 -1.65527585011815E-05 -0.110857092842009"
        rpy="0 0 0" />
      <mass
        value="0.0687228409087856" />
      <inertia
        ixx="6.42198625809038E-05"
        ixy="-8.56742150772802E-09"
        ixz="-1.18644635684186E-08"
        iyy="6.99945188679626E-05"
        iyz="6.46876985469347E-11"
        izz="1.55422946691621E-05" />
    </inertial>
    <visual>
      <origin
        xyz="0 0 0"
        rpy="0 0 0" />
      <geometry>
        <mesh
          filename="package://Quad/meshes/BR_Shin.STL" />
      </geometry>
      <material
        name="">
        <color
          rgba="0.792156862745098 0.819607843137255 0.933333333333333 1" />
      </material>
    </visual>
    <collision>
      <origin
        xyz="0 0 0"
        rpy="0 0 0" />
      <geometry>
        <mesh
          filename="package://Quad/meshes/BR_Shin.STL" />
      </geometry>
    </collision>
  </link>
  <joint
    name="BR_J3"
    type="continuous">
    <origin
      xyz="0 0 -0.318"
      rpy="0 0 0" />
    <parent
      link="BR_Thigh" />
    <child
      link="BR_Shin" />
    <axis
      xyz="-1 0 0" />
  </joint>
  <link
    name="BL_Hip">
    <inertial>
      <origin
        xyz="0.0192378662036614 -1.78144100027033E-08 -0.0297489009840162"
        rpy="0 0 0" />
      <mass
        value="0.244991783639187" />
      <inertia
        ixx="0.000239714320228986"
        ixy="-5.46133415454717E-12"
        ixz="-3.29715835980666E-12"
        iyy="0.000161925907771085"
        iyz="-2.25080068073244E-10"
        izz="0.000229565612565136" />
    </inertial>
    <visual>
      <origin
        xyz="0 0 0"
        rpy="0 0 0" />
      <geometry>
        <mesh
          filename="package://Quad/meshes/BL_Hip.STL" />
      </geometry>
      <material
        name="">
        <color
          rgba="0.00784313725490196 0.23921568627451 0.823529411764706 1" />
      </material>
    </visual>
    <collision>
      <origin
        xyz="0 0 0"
        rpy="0 0 0" />
      <geometry>
        <mesh
          filename="package://Quad/meshes/BL_Hip.STL" />
      </geometry>
    </collision>
  </link>
  <joint
    name="BL_J1"
    type="continuous">
    <origin
      xyz="0.1 0.05 -0.205567"
      rpy="0 0 0" />
    <parent
      link="Body" />
    <child
      link="BL_Hip" />
    <axis
      xyz="0 0 1" />
  </joint>
  <link
    name="BL_Thigh">
    <inertial>
      <origin
        xyz="-0.0213045756655136 5.1836889221335E-07 -0.112532577948083"
        rpy="0 0 0" />
      <mass
        value="0.248973034603069" />
      <inertia
        ixx="0.00036258733750292"
        ixy="1.17555629152012E-10"
        ixz="-2.90184454491026E-06"
        iyy="0.000199472018852034"
        iyz="1.98376638237396E-08"
        izz="0.000193599008816691" />
    </inertial>
    <visual>
      <origin
        xyz="0 0 0"
        rpy="0 0 0" />
      <geometry>
        <mesh
          filename="package://Quad/meshes/BL_Thigh.STL" />
      </geometry>
      <material
        name="">
        <color
          rgba="0.00784313725490196 0.23921568627451 0.823529411764706 1" />
      </material>
    </visual>
    <collision>
      <origin
        xyz="0 0 0"
        rpy="0 0 0" />
      <geometry>
        <mesh
          filename="package://Quad/meshes/BL_Thigh.STL" />
      </geometry>
    </collision>
  </link>
  <joint
    name="BL_J2"
    type="continuous">
    <origin
      xyz="0.0700000000000002 0 -0.045979703345944"
      rpy="0 0 0" />
    <parent
      link="BL_Hip" />
    <child
      link="BL_Thigh" />
    <axis
      xyz="-1 0 0" />
  </joint>
  <link
    name="BL_Shin">
    <inertial>
      <origin
        xyz="-0.00941299977249625 1.65527585011677E-05 -0.110857092842009"
        rpy="0 0 0" />
      <mass
        value="0.0687228409087855" />
      <inertia
        ixx="6.42198625809038E-05"
        ixy="-8.56742150772928E-09"
        ixz="1.1864463568417E-08"
        iyy="6.99945188679626E-05"
        iyz="-6.46876985465356E-11"
        izz="1.55422946691621E-05" />
    </inertial>
    <visual>
      <origin
        xyz="0 0 0"
        rpy="0 0 0" />
      <geometry>
        <mesh
          filename="package://Quad/meshes/BL_Shin.STL" />
      </geometry>
      <material
        name="">
        <color
          rgba="0.286274509803922 0.662745098039216 0.329411764705882 1" />
      </material>
    </visual>
    <collision>
      <origin
        xyz="0 0 0"
        rpy="0 0 0" />
      <geometry>
        <mesh
          filename="package://Quad/meshes/BL_Shin.STL" />
      </geometry>
    </collision>
  </link>
  <joint
    name="BL_J3"
    type="continuous">
    <origin
      xyz="0 0 -0.318"
      rpy="0 0 0" />
    <parent
      link="BL_Thigh" />
    <child
      link="BL_Shin" />
    <axis
      xyz="1 0 0" />
  </joint>
</robot>