<?xml version="1.0" encoding="utf-8"?>
<!-- This URDF was automatically created by SolidWorks to URDF Exporter! Originally created by Stephen Brawner (brawner@gmail.com) 
     Commit Version: 1.6.0-4-g7f85cfe  Build Version: 1.6.7995.38578
     For more information, please see http://wiki.ros.org/sw_urdf_exporter -->
<robot
  name="Biped_NoWheels">
  <link
    name="Body">
    <inertial>
      <origin
        xyz="0.00875 -0.00011577 0.049281"
        rpy="0 0 0" />
      <mass
        value="0.5" />
      <inertia
        ixx="0.016664"
        ixy="-2.5802E-16"
        ixz="-2.5495E-05"
        iyy="0.01491"
        iyz="3.7322E-12"
        izz="0.025732" />
    </inertial>
    <visual>
      <origin
        xyz="0 0 0"
        rpy="0 0 0" />
      <geometry>
        <mesh
          filename="../meshes/Body.STL" />
      </geometry>
      <material
        name="">
        <color
          rgba="0.28627 0.66275 0.32941 1" />
      </material>
    </visual>
    <collision>
      <origin
        xyz="0 0 0"
        rpy="0 0 0" />
      <geometry>
        <mesh
          filename="../meshes/Body.STL" />
      </geometry>
    </collision>
  </link>
  <link
    name="L_Hip">
    <inertial>
      <origin
        xyz="-0.029749 0.019238 -1.7814E-08"
        rpy="0 0 0" />
      <mass
        value="0.24499" />
      <inertia
        ixx="0.00022957"
        ixy="-3.2972E-12"
        ixz="-2.2508E-10"
        iyy="0.00023971"
        iyz="-5.4613E-12"
        izz="0.00016193" />
    </inertial>
    <visual>
      <origin
        xyz="0 0 0"
        rpy="0 0 0" />
      <geometry>
        <mesh
          filename="../meshes/L_Hip.STL" />
      </geometry>
      <material
        name="">
        <color
          rgba="0.0078431 0.23922 0.82353 1" />
      </material>
    </visual>
    <collision>
      <origin
        xyz="0 0 0"
        rpy="0 0 0" />
      <geometry>
        <mesh
          filename="../meshes/L_Hip.STL" />
      </geometry>
    </collision>
  </link>
  <joint
    name="L_J1"
    type="revolute">
    <origin
      xyz="0.034433 0.1 0.05"
      rpy="0 0 0" />
    <parent
      link="Body" />
    <child
      link="L_Hip" />
    <axis
      xyz="1 0 0" />
    <limit
      lower="-0.35"
      upper="0.35"
      effort="2"
      velocity="0" />
  </joint>
  <link
    name="L_Thigh">
    <inertial>
      <origin
        xyz="-0.098727 -0.021408 5.2332E-07"
        rpy="0 0 0" />
      <mass
        value="0.24662" />
      <inertia
        ixx="0.00019357"
        ixy="-2.9018E-06"
        ixz="1.9838E-08"
        iyy="0.00032526"
        iyz="1.1756E-10"
        izz="0.00016215" />
    </inertial>
    <visual>
      <origin
        xyz="0 0 0"
        rpy="0 0 0" />
      <geometry>
        <mesh
          filename="../meshes/L_Thigh.STL" />
      </geometry>
      <material
        name="">
        <color
          rgba="0.0078431 0.23922 0.82353 1" />
      </material>
    </visual>
    <collision>
      <origin
        xyz="0 0 0"
        rpy="0 0 0" />
      <geometry>
        <mesh
          filename="../meshes/L_Thigh.STL" />
      </geometry>
    </collision>
  </link>
  <joint
    name="L_J2"
    type="revolute">
    <origin
      xyz="-0.04598 0.07 0"
      rpy="0 0 0" />
    <parent
      link="L_Hip" />
    <child
      link="L_Thigh" />
    <axis
      xyz="0 -1 0" />
    <limit
      lower="-2.8"
      upper="2.8"
      effort="2"
      velocity="0" />
  </joint>
  <link
    name="L_Shin">
    <inertial>
      <origin
        xyz="-0.083975 -0.0098423 1.5717E-05"
        rpy="0 0 0" />
      <mass
        value="0.072375" />
      <inertia
        ixx="1.209E-05"
        ixy="1.1864E-08"
        ixz="-6.4688E-11"
        iyy="2.9394E-05"
        iyz="-8.568E-09"
        izz="2.7528E-05" />
    </inertial>
    <visual>
      <origin
        xyz="0 0 0"
        rpy="0 0 0" />
      <geometry>
        <mesh
          filename="../meshes/L_Shin.STL" />
      </geometry>
      <material
        name="">
        <color
          rgba="0.79216 0.81961 0.93333 1" />
      </material>
    </visual>
    <collision>
      <origin
        xyz="0 0 0"
        rpy="0 0 0" />
      <geometry>
        <mesh
          filename="../meshes/L_Shin.STL" />
      </geometry>
    </collision>
  </link>
  <joint
    name="L_J3"
    type="revolute">
    <origin
      xyz="-0.218 0 0"
      rpy="0 0 0" />
    <parent
      link="L_Thigh" />
    <child
      link="L_Shin" />
    <axis
      xyz="0 1 0" />
    <limit
      lower="-2.8"
      upper="2.8"
      effort="2"
      velocity="0" />
  </joint>
  <link
    name="R_Hip">
    <inertial>
      <origin
        xyz="-0.029749 -0.019238 1.7814E-08"
        rpy="0 0 0" />
      <mass
        value="0.24499" />
      <inertia
        ixx="0.00022957"
        ixy="3.2972E-12"
        ixz="2.2508E-10"
        iyy="0.00023971"
        iyz="-5.4613E-12"
        izz="0.00016193" />
    </inertial>
    <visual>
      <origin
        xyz="0 0 0"
        rpy="0 0 0" />
      <geometry>
        <mesh
          filename="../meshes/R_Hip.STL" />
      </geometry>
      <material
        name="">
        <color
          rgba="0.0078431 0.23922 0.82353 1" />
      </material>
    </visual>
    <collision>
      <origin
        xyz="0 0 0"
        rpy="0 0 0" />
      <geometry>
        <mesh
          filename="../meshes/R_Hip.STL" />
      </geometry>
    </collision>
  </link>
  <joint
    name="R_J1"
    type="revolute">
    <origin
      xyz="0.034433 -0.1 0.05"
      rpy="0 0 0" />
    <parent
      link="Body" />
    <child
      link="R_Hip" />
    <axis
      xyz="1 0 0" />
    <limit
      lower="-0.35"
      upper="0.35"
      effort="2"
      velocity="0" />
  </joint>
  <link
    name="R_Thigh">
    <inertial>
      <origin
        xyz="-0.098727 0.021408 -5.2332E-07"
        rpy="0 0 0" />
      <mass
        value="0.24662" />
      <inertia
        ixx="0.00019357"
        ixy="2.9018E-06"
        ixz="-1.9838E-08"
        iyy="0.00032526"
        iyz="1.1756E-10"
        izz="0.00016215" />
    </inertial>
    <visual>
      <origin
        xyz="0 0 0"
        rpy="0 0 0" />
      <geometry>
        <mesh
          filename="../meshes/R_Thigh.STL" />
      </geometry>
      <material
        name="">
        <color
          rgba="0.79216 0.81961 0.93333 1" />
      </material>
    </visual>
    <collision>
      <origin
        xyz="0 0 0"
        rpy="0 0 0" />
      <geometry>
        <mesh
          filename="../meshes/R_Thigh.STL" />
      </geometry>
    </collision>
  </link>
  <joint
    name="R_J2"
    type="revolute">
    <origin
      xyz="-0.04598 -0.07 0"
      rpy="0 0 0" />
    <parent
      link="R_Hip" />
    <child
      link="R_Thigh" />
    <axis
      xyz="0 1 0" />
    <limit
      lower="-2.8"
      upper="2.8"
      effort="2"
      velocity="0" />
  </joint>
  <link
    name="R_Shin">
    <inertial>
      <origin
        xyz="-0.083975 0.0098423 -1.5717E-05"
        rpy="0 0 0" />
      <mass
        value="0.072375" />
      <inertia
        ixx="1.209E-05"
        ixy="-1.1864E-08"
        ixz="6.4688E-11"
        iyy="2.9394E-05"
        iyz="-8.568E-09"
        izz="2.7528E-05" />
    </inertial>
    <visual>
      <origin
        xyz="0 0 0"
        rpy="0 0 0" />
      <geometry>
        <mesh
          filename="../meshes/R_Shin.STL" />
      </geometry>
      <material
        name="">
        <color
          rgba="0.79216 0.81961 0.93333 1" />
      </material>
    </visual>
    <collision>
      <origin
        xyz="0 0 0"
        rpy="0 0 0" />
      <geometry>
        <mesh
          filename="../meshes/R_Shin.STL" />
      </geometry>
    </collision>
  </link>
  <joint
    name="R_J3"
    type="revolute">
    <origin
      xyz="-0.218 0 0"
      rpy="0 0 0" />
    <parent
      link="R_Thigh" />
    <child
      link="R_Shin" />
    <axis
      xyz="0 -1 0" />
    <limit
      lower="-2.8"
      upper="2.8"
      effort="2"
      velocity="0" />
  </joint>
</robot>