<?xml version="1.0" encoding="utf-8"?>
<!-- This URDF was automatically created by SolidWorks to URDF Exporter! Originally created by Stephen Brawner (brawner@gmail.com) 
     Commit Version: 1.6.0-4-g7f85cfe  Build Version: 1.6.7995.38578
     For more information, please see http://wiki.ros.org/sw_urdf_exporter -->
<robot
  name="TorquePoleLong">
  <link
    name="base_link">
    <inertial>
      <origin
        xyz="-0.014371 0.00028403 -0.46179"
        rpy="0 0 0" />
      <mass
        value="0.36931" />
      <inertia
        ixx="0.00069867"
        ixy="1.9195E-10"
        ixz="1.1612E-06"
        iyy="0.00050718"
        iyz="1.3223E-09"
        izz="0.00038222" />
    </inertial>
    <visual>
      <origin
        xyz="0 0 0"
        rpy="0 0 0" />
      <geometry>
        <mesh
          filename="package://TorquePoleLong/meshes/base_link.STL" />
      </geometry>
      <material
        name="">
        <color
          rgba="0.79216 0.81961 0.93333 1" />
      </material>
    </visual>
    <collision>
      <origin
        xyz="0 0 0"
        rpy="0 0 0" />
      <geometry>
        <mesh
          filename="package://TorquePoleLong/meshes/base_link.STL" />
      </geometry>
    </collision>
  </link>
  <link
    name="pendulum">
    <inertial>
      <origin
        xyz="-0.0039932 -0.18792 -2.1363E-05"
        rpy="0 0 0" />
      <mass
        value="0.073435" />
      <inertia
        ixx="0.00025668"
        ixy="-8.6352E-09"
        ixz="-1.1815E-08"
        iyy="1.5609E-05"
        iyz="6.4928E-11"
        izz="0.00026245" />
    </inertial>
    <visual>
      <origin
        xyz="0 0 0"
        rpy="0 0 0" />
      <geometry>
        <mesh
          filename="package://TorquePoleLong/meshes/pendulum.STL" />
      </geometry>
      <material
        name="">
        <color
          rgba="0.79216 0.81961 0.93333 1" />
      </material>
    </visual>
    <collision>
      <origin
        xyz="0 0 0"
        rpy="0 0 0" />
      <geometry>
        <mesh
          filename="package://TorquePoleLong/meshes/pendulum.STL" />
      </geometry>
    </collision>
  </link>
  <joint
    name="PullyJoint"
    type="revolute">
    <origin
      xyz="0 0 0"
      rpy="0 0 0" />
    <parent
      link="base_link" />
    <child
      link="pendulum" />
    <axis
      xyz="-1 0 0" />
    <limit
      lower="-1.35"
      upper="4.5"
      effort="3"
      velocity="60" />
  </joint>
</robot>