<?xml version="1.0" encoding="utf-8"?>
<!-- This URDF was automatically created by SolidWorks to URDF Exporter! Originally created by Stephen Brawner (brawner@gmail.com) 
     Commit Version: 1.6.0-4-g7f85cfe  Build Version: 1.6.7995.38578
     For more information, please see http://wiki.ros.org/sw_urdf_exporter -->
<robot
  name="Leg">
  <link
    name="base_link">
    <inertial>
      <origin
        xyz="0 0 0.5"
        rpy="0 0 0" />
      <mass
        value="0.050265" />
      <inertia
        ixx="0.004189"
        ixy="-6.8932E-24"
        ixz="-1.7647E-21"
        iyy="0.004189"
        iyz="2.2058E-22"
        izz="4.0212E-07" />
    </inertial>
    <visual>
      <origin
        xyz="0 0 0"
        rpy="0 0 0" />
      <geometry>
        <mesh
          filename="package://Leg/meshes/base_link.STL" />
      </geometry>
      <material
        name="">
        <color
          rgba="0.79216 0.81961 0.93333 1" />
      </material>
    </visual>
    <collision>
      <origin
        xyz="0 0 0"
        rpy="0 0 0" />
      <geometry>
        <mesh
          filename="package://Leg/meshes/base_link.STL" />
      </geometry>
    </collision>
  </link>
  <link
    name="LinearGuide">
    <inertial>
      <origin
        xyz="-4.0944E-10 0.042042 0.50798"
        rpy="0 0 0" />
      <mass
        value="0.1155" />
      <inertia
        ixx="3.9031E-05"
        ixy="-4.83E-13"
        ixz="-1.2809E-12"
        iyy="6.9244E-05"
        iyz="-1.0031E-09"
        izz="3.9042E-05" />
    </inertial>
    <visual>
      <origin
        xyz="0 0 0"
        rpy="0 0 0" />
      <geometry>
        <mesh
          filename="package://Leg/meshes/LinearGuide.STL" />
      </geometry>
      <material
        name="">
        <color
          rgba="0.79216 0.81961 0.93333 1" />
      </material>
    </visual>
    <collision>
      <origin
        xyz="0 0 0"
        rpy="0 0 0" />
      <geometry>
        <mesh
          filename="package://Leg/meshes/LinearGuide.STL" />
      </geometry>
    </collision>
  </link>
  <joint
    name="LinearGuide"
    type="prismatic">
    <origin
      xyz="0 0 0"
      rpy="0 0 0" />
    <parent
      link="base_link" />
    <child
      link="LinearGuide" />
    <axis
      xyz="0 0 1" />
    <limit
      lower="0"
      upper="1"
      effort="0"
      velocity="0" />
  </joint>
  <link
    name="Rot1">
    <inertial>
      <origin
        xyz="-0.15198 0.036958 -0.152"
        rpy="0 0 0" />
      <mass
        value="0.19486" />
      <inertia
        ixx="0.00014931"
        ixy="-1.0633E-06"
        ixz="-2.2254E-05"
        iyy="0.00027811"
        iyz="-1.0754E-06"
        izz="0.00014918" />
    </inertial>
    <visual>
      <origin
        xyz="0 0 0"
        rpy="0 0 0" />
      <geometry>
        <mesh
          filename="package://Leg/meshes/Rot1.STL" />
      </geometry>
      <material
        name="">
        <color
          rgba="0.77647 0.75686 0.73725 1" />
      </material>
    </visual>
    <collision>
      <origin
        xyz="0 0 0"
        rpy="0 0 0" />
      <geometry>
        <mesh
          filename="package://Leg/meshes/Rot1.STL" />
      </geometry>
    </collision>
  </link>
  <joint
    name="Rot1"
    type="revolute">
    <origin
      xyz="0 0.031 0.508"
      rpy="0 0 0" />
    <parent
      link="LinearGuide" />
    <child
      link="Rot1" />
    <axis
      xyz="0 -1 0" />
    <limit
      lower="-1.5708"
      upper="1.5708"
      effort="3"
      velocity="300" />
  </joint>
  <link
    name="Rot2">
    <inertial>
      <origin
        xyz="0.073904 0.030122 -0.073868"
        rpy="0 0 0" />
      <mass
        value="0.10648" />
      <inertia
        ixx="0.00011939"
        ixy="1.6228E-06"
        ixz="2.1114E-05"
        iyy="0.00022638"
        iyz="-1.6108E-06"
        izz="0.00011952" />
    </inertial>
    <visual>
      <origin
        xyz="0 0 0"
        rpy="0 0 0" />
      <geometry>
        <mesh
          filename="package://Leg/meshes/Rot2.STL" />
      </geometry>
      <material
        name="">
        <color
          rgba="0.77647 0.75686 0.73725 1" />
      </material>
    </visual>
    <collision>
      <origin
        xyz="0 0 0"
        rpy="0 0 0" />
      <geometry>
        <mesh
          filename="package://Leg/meshes/Rot2.STL" />
      </geometry>
    </collision>
  </link>
  <joint
    name="Rot2"
    type="revolute">
    <origin
      xyz="-0.24607 0.025 -0.24607"
      rpy="0 0 0" />
    <parent
      link="Rot1" />
    <child
      link="Rot2" />
    <axis
      xyz="0 -1 0" />
    <limit
      lower="-1.5708"
      upper="1.5708"
      effort="3"
      velocity="300" />
  </joint>
</robot>