<?xml version="1.0" encoding="utf-8"?>
<!-- This URDF was automatically created by SolidWorks to URDF Exporter! Originally created by Stephen Brawner (brawner@gmail.com) 
     Commit Version: 1.6.0-4-g7f85cfe  Build Version: 1.6.7995.38578
     For more information, please see http://wiki.ros.org/sw_urdf_exporter -->
<robot
  name="TorquePole2">
  <link
    name="base_link">
    <inertial>
      <origin
        xyz="0.004735 -9.5049E-08 0.029199"
        rpy="0 0 0" />
      <mass
        value="0.13052" />
      <inertia
        ixx="8.7064E-05"
        ixy="-1.1929E-09"
        ixz="-2.1711E-06"
        iyy="0.00032409"
        iyz="2.8698E-10"
        izz="0.00038694" />
    </inertial>
    <visual>
      <origin
        xyz="0 0 0"
        rpy="0 0 0" />
      <geometry>
        <mesh
          filename="package://TorquePole2/meshes/base_link.STL" />
      </geometry>
      <material
        name="">
        <color
          rgba="0.79216 0.81961 0.93333 1" />
      </material>
    </visual>
    <collision>
      <origin
        xyz="0 0 0"
        rpy="0 0 0" />
      <geometry>
        <mesh
          filename="package://TorquePole2/meshes/base_link.STL" />
      </geometry>
    </collision>
  </link>
  <link
    name="pendulum_link">
    <inertial>
      <origin
        xyz="8.1535E-11 -0.057063 0.044048"
        rpy="0 0 0" />
      <mass
        value="0.027671" />
      <inertia
        ixx="0.00012638"
        ixy="-6.8173E-09"
        ixz="-4.9901E-14"
        iyy="3.2322E-06"
        iyz="-1.9833E-08"
        izz="0.00012821" />
    </inertial>
    <visual>
      <origin
        xyz="0 0 0"
        rpy="0 0 0" />
      <geometry>
        <mesh
          filename="package://TorquePole2/meshes/pendulum_link.STL" />
      </geometry>
      <material
        name="">
        <color
          rgba="0.79216 0.81961 0.93333 1" />
      </material>
    </visual>
    <collision>
      <origin
        xyz="0 0 0"
        rpy="0 0 0" />
      <geometry>
        <mesh
          filename="package://TorquePole2/meshes/pendulum_link.STL" />
      </geometry>
    </collision>
  </link>
  <joint
    name="pendulum"
    type="continuous">
    <origin
      xyz="0 0 0"
      rpy="0 0 0" />
    <parent
      link="base_link" />
    <child
      link="pendulum_link" />
    <axis
      xyz="0 0 -1" />
    <limit
      effort="0.5"
      velocity="3000" />
  </joint>
</robot>