<?xml version="1.0" encoding="utf-8"?>
<!-- This URDF was automatically created by SolidWorks to URDF Exporter! Originally created by Stephen Brawner (brawner@gmail.com) 
     Commit Version: 1.6.0-4-g7f85cfe  Build Version: 1.6.7995.38578
     For more information, please see http://wiki.ros.org/sw_urdf_exporter -->
<robot
  name="Biped">
  <link
    name="Body">
    <inertial>
      <origin
        xyz="0.0095103752478065 -0.000109841105733977 0.0493179617384485"
        rpy="0 0 0" />
      <mass
        value="0.5" />
      <inertia
        ixx="0.019518633329031"
        ixy="-2.54552978084444E-16"
        ixz="-3.49702762359798E-05"
        iyy="0.0158248427856157"
        iyz="2.20677522985431E-12"
        izz="0.0293402569206354" />
    </inertial>
    <visual>
      <origin
        xyz="0 0 0"
        rpy="0 0 0" />
      <geometry>
        <mesh
          filename="../meshes/Body.STL" />
      </geometry>
      <material
        name="">
        <color
          rgba="0.286274509803922 0.662745098039216 0.329411764705882 1" />
      </material>
    </visual>
    <collision>
      <origin
        xyz="0 0 0"
        rpy="0 0 0" />
      <geometry>
        <mesh
          filename="../meshes/Body.STL" />
      </geometry>
    </collision>
  </link>
  <link
    name="L_Hip">
    <inertial>
      <origin
        xyz="-0.0297489037061823 0.0192378682963179 -1.7711660318942E-08"
        rpy="0 0 0" />
      <mass
        value="0.244991798913576" />
      <inertia
        ixx="0.00022956561268953"
        ixy="-2.41539107841904E-12"
        ixz="-2.24317340219231E-10"
        iyy="0.00023971433240892"
        iyz="-5.50158044201733E-12"
        izz="0.000161925920118534" />
    </inertial>
    <visual>
      <origin
        xyz="0 0 0"
        rpy="0 0 0" />
      <geometry>
        <mesh
          filename="../meshes/L_Hip.STL" />
      </geometry>
      <material
        name="">
        <color
          rgba="0.00784313725490196 0.23921568627451 0.823529411764706 1" />
      </material>
    </visual>
    <!-- <collision>
      <origin
        xyz="0 0 0"
        rpy="0 0 0" />
      <geometry>
        <mesh
          filename="../meshes/L_Hip.STL" />
      </geometry>
    </collision> -->
  </link>
  <joint
    name="L_J1"
    type="revolute">
    <origin
      xyz="-0.00556699999999997 0.1 0.05"
      rpy="0 0 0" />
    <parent
      link="Body" />
    <child
      link="L_Hip" />
    <axis
      xyz="1 0 0" />
    <limit
      lower="-0.35"
      upper="0.35"
      effort="2"
      velocity="0" />
  </joint>
  <link
    name="L_Thigh">
    <inertial>
      <origin
        xyz="-0.0987271588891236 -0.0214078033349625 5.23321424458767E-07"
        rpy="0 0 0" />
      <mass
        value="0.246616840112844" />
      <inertia
        ixx="0.000193565727569489"
        ixy="-2.90184454491118E-06"
        ixz="1.98376638289771E-08"
        iyy="0.000325264284117897"
        iyz="1.17555628547022E-10"
        izz="0.00016214896546703" />
    </inertial>
    <visual>
      <origin
        xyz="0 0 0"
        rpy="0 0 0" />
      <geometry>
        <mesh
          filename="../meshes/L_Thigh.STL" />
      </geometry>
      <material
        name="">
        <color
          rgba="0.00784313725490196 0.23921568627451 0.823529411764706 1" />
      </material>
    </visual>
    <!-- <collision>
      <origin
        xyz="0 0 0"
        rpy="0 0 0" />
      <geometry>
        <mesh
          filename="../meshes/L_Thigh.STL" />
      </geometry>
    </collision> -->
  </link>
  <joint
    name="L_J2"
    type="revolute">
    <origin
      xyz="-0.045979703345944 0.07 0"
      rpy="0 0 0" />
    <parent
      link="L_Hip" />
    <child
      link="L_Thigh" />
    <axis
      xyz="0 -1 0" />
    <limit
      lower="-2.8"
      upper="2.8"
      effort="2"
      velocity="0" />
  </joint>
  <link
    name="L_Shin">
    <inertial>
      <origin
        xyz="-0.0735417570461924 -0.00942766237548921 1.71404259591001E-05"
        rpy="0 0 0" />
      <mass
        value="0.0663666464185944" />
      <inertia
        ixx="1.55090134219887E-05"
        ixy="1.18644635683977E-08"
        ixz="-6.46876985041904E-11"
        iyy="2.68968091959369E-05"
        iyz="-8.56742150772773E-09"
        izz="3.2671465482996E-05" />
    </inertial>
    <visual>
      <origin
        xyz="0 0 0"
        rpy="0 0 0" />
      <geometry>
        <mesh
          filename="../meshes/L_Shin.STL" />
      </geometry>
      <material
        name="">
        <color
          rgba="0.792156862745098 0.819607843137255 0.933333333333333 1" />
      </material>
    </visual>
    <collision>
      <origin
        xyz="0 0 0"
        rpy="0 0 0" />
      <geometry>
        <mesh
          filename="../meshes/L_Shin.STL" />
      </geometry>
    </collision>
  </link>
  <joint
    name="L_J3"
    type="revolute">
    <origin
      xyz="-0.218 0 0"
      rpy="0 0 0" />
    <parent
      link="L_Thigh" />
    <child
      link="L_Shin" />
    <axis
      xyz="0 1 0" />
    <limit
      lower="-2.8"
      upper="2.8"
      effort="2"
      velocity="0" />
  </joint>
  <link
    name="R_Hip">
    <inertial>
      <origin
        xyz="-0.0297489009840183 -0.019237866203657 1.78144084345133E-08"
        rpy="0 0 0" />
      <mass
        value="0.244991783639153" />
      <inertia
        ixx="0.000229565612565129"
        ixy="3.29715605345702E-12"
        ixz="2.25080059309325E-10"
        iyy="0.000239714320228954"
        iyz="-5.46133708582936E-12"
        izz="0.000161925907771057" />
    </inertial>
    <visual>
      <origin
        xyz="0 0 0"
        rpy="0 0 0" />
      <geometry>
        <mesh
          filename="../meshes/R_Hip.STL" />
      </geometry>
      <material
        name="">
        <color
          rgba="0.00784313725490196 0.23921568627451 0.823529411764706 1" />
      </material>
    </visual>
    <collision>
      <origin
        xyz="0 0 0"
        rpy="0 0 0" />
      <geometry>
        <mesh
          filename="../meshes/R_Hip.STL" />
      </geometry>
    </collision>
  </link>
  <joint
    name="R_J1"
    type="revolute">
    <origin
      xyz="-0.00556700000000009 -0.1 0.05"
      rpy="0 0 0" />
    <parent
      link="Body" />
    <child
      link="R_Hip" />
    <axis
      xyz="1 0 0" />
    <limit
      lower="-0.35"
      upper="0.35"
      effort="2"
      velocity="0" />
  </joint>
  <link
    name="R_Thigh">
    <inertial>
      <origin
        xyz="-0.098056644783453 0.0190172671660884 -5.6116251226368E-07"
        rpy="0 0 0" />
      <mass
        value="0.229986631658005" />
      <inertia
        ixx="0.000188613135524103"
        ixy="2.90184454491106E-06"
        ixz="-1.9837663828111E-08"
        iyy="0.00031545884636905"
        iyz="1.17555628405258E-10"
        izz="0.000157196373421645" />
    </inertial>
    <visual>
      <origin
        xyz="0 0 0"
        rpy="0 0 0" />
      <geometry>
        <mesh
          filename="../meshes/R_Thigh.STL" />
      </geometry>
      <material
        name="">
        <color
          rgba="0.792156862745098 0.819607843137255 0.933333333333333 1" />
      </material>
    </visual>
    <collision>
      <origin
        xyz="0 0 0"
        rpy="0 0 0" />
      <geometry>
        <mesh
          filename="../meshes/R_Thigh.STL" />
      </geometry>
    </collision>
  </link>
  <joint
    name="R_J2"
    type="revolute">
    <origin
      xyz="-0.045979703345944 -0.07 0"
      rpy="0 0 0" />
    <parent
      link="R_Hip" />
    <child
      link="R_Thigh" />
    <axis
      xyz="0 1 0" />
    <limit
      lower="-2.8"
      upper="2.8"
      effort="2"
      velocity="0" />
  </joint>
  <link
    name="R_Shin">
    <inertial>
      <origin
        xyz="-0.0735417570461923 0.00942766237548914 -1.71404259590863E-05"
        rpy="0 0 0" />
      <mass
        value="0.0663666464185944" />
      <inertia
        ixx="1.55090134219886E-05"
        ixy="-1.18644635683982E-08"
        ixz="6.46876985037832E-11"
        iyy="2.68968091959368E-05"
        iyz="-8.56742150772691E-09"
        izz="3.26714654829959E-05" />
    </inertial>
    <visual>
      <origin
        xyz="0 0 0"
        rpy="0 0 0" />
      <geometry>
        <mesh
          filename="../meshes/R_Shin.STL" />
      </geometry>
      <material
        name="">
        <color
          rgba="0.792156862745098 0.819607843137255 0.933333333333333 1" />
      </material>
    </visual>
    <collision>
      <origin
        xyz="0 0 0"
        rpy="0 0 0" />
      <geometry>
        <mesh
          filename="../meshes/R_Shin.STL" />
      </geometry>
    </collision>
  </link>
  <joint
    name="R_J3"
    type="revolute">
    <origin
      xyz="-0.218 0 0"
      rpy="0 0 0" />
    <parent
      link="R_Thigh" />
    <child
      link="R_Shin" />
    <axis
      xyz="0 -1 0" />
    <limit
      lower="-2.8"
      upper="2.8"
      effort="2"
      velocity="0" />
  </joint>
  <link
    name="ReactionWheelX">
    <inertial>
      <origin
        xyz="0 2.7756E-17 1.3878E-17"
        rpy="0 0 0" />
      <mass
        value="0.25" />
      <inertia
        ixx="0.00023479"
        ixy="-3.0975E-21"
        ixz="3.9219E-23"
        iyy="0.0001185"
        iyz="1.8519E-20"
        izz="0.0001185" />
    </inertial>
    <visual>
      <origin
        xyz="0 0 0"
        rpy="0 0 0" />
      <geometry>
        <mesh
          filename="../meshes/ReactionWheelX.STL" />
      </geometry>
      <material
        name="">
        <color
          rgba="0.79216 0.81961 0.93333 1" />
      </material>
    </visual>
  </link>
  <joint
    name="WheelX"
    type="continuous">
    <origin
      xyz="-0.0699999999999999 0 0.05"
      rpy="0 0 0" />
    <parent
      link="Body" />
    <child
      link="ReactionWheelX" />
    <axis
      xyz="1 0 0" />
  </joint>
  <link
    name="ReactionWheelY">
    <inertial>
      <origin
        xyz="0 2.7756E-17 1.3878E-17"
        rpy="0 0 0" />
      <mass
        value="0.25" />
      <inertia
        ixx="0.0001185"
        ixy="-4.9598E-21"
        ixz="-3.4328E-20"
        iyy="0.00023479"
        iyz="1.5862E-21"
        izz="0.0001185" />
    </inertial>
    <visual>
      <origin
        xyz="0 0 0"
        rpy="0 0 0" />
      <geometry>
        <mesh
          filename="../meshes/ReactionWheelY.STL" />
      </geometry>
      <material
        name="">
        <color
          rgba="0.79216 0.81961 0.93333 1" />
      </material>
    </visual>
  </link>
  <joint
    name="WheelY"
    type="continuous">
    <origin
      xyz="0.020147207668468 0 0.05"
      rpy="0 0 0" />
    <parent
      link="Body" />
    <child
      link="ReactionWheelY" />
    <axis
      xyz="0 1 0" />
  </joint>
</robot>