<?xml version="1.0" encoding="utf-8"?>
<!-- This URDF was automatically created by SolidWorks to URDF Exporter! Originally created by Stephen Brawner (brawner@gmail.com) 
     Commit Version: 1.6.0-4-g7f85cfe  Build Version: 1.6.7995.38578
     For more information, please see http://wiki.ros.org/sw_urdf_exporter -->
<robot
  name="Biped">
  <link
    name="Body">
    <inertial>
      <origin
        xyz="-0.00035328366311746 0.0500000000000054 0.00456008585168246"
        rpy="0 0 0" />
      <mass
        value="7.70955702097607" />
      <inertia
        ixx="0.0619957543602243"
        ixy="-4.50160138213646E-10"
        ixz="1.56744022092454E-18"
        iyy="0.0971953992943034"
        iyz="4.95401587370608E-16"
        izz="0.0465638617649732" />
    </inertial>
    <visual>
      <origin
        xyz="0 0 0"
        rpy="0 0 0" />
      <geometry>
        <mesh
          filename="package://Biped/meshes/Body.STL" />
      </geometry>
      <material
        name="">
        <color
          rgba="0.286274509803922 0.662745098039216 0.329411764705882 1" />
      </material>
    </visual>
    <collision>
      <origin
        xyz="0 0 0"
        rpy="0 0 0" />
      <geometry>
        <mesh
          filename="package://Biped/meshes/Body.STL" />
      </geometry>
    </collision>
  </link>
  <link
    name="FR_Hip">
    <inertial>
      <origin
        xyz="-0.0192378662036576 -1.78144080875686E-08 0.0297489009840207"
        rpy="0 0 0" />
      <mass
        value="0.24499178363917" />
      <inertia
        ixx="0.000239714320229003"
        ixy="5.46133907520433E-12"
        ixz="-3.29715487077482E-12"
        iyy="0.000161925907771085"
        iyz="2.25080068619392E-10"
        izz="0.000229565612565153" />
    </inertial>
    <visual>
      <origin
        xyz="0 0 0"
        rpy="0 0 0" />
      <geometry>
        <mesh
          filename="package://Biped/meshes/FR_Hip.STL" />
      </geometry>
      <material
        name="">
        <color
          rgba="0.00784313725490196 0.23921568627451 0.823529411764706 1" />
      </material>
    </visual>
    <collision>
      <origin
        xyz="0 0 0"
        rpy="0 0 0" />
      <geometry>
        <mesh
          filename="package://Biped/meshes/FR_Hip.STL" />
      </geometry>
    </collision>
  </link>
  <joint
    name="FR_J1"
    type="continuous">
    <origin
      xyz="-0.1 0.05 0.205567"
      rpy="0 0 0" />
    <parent
      link="Body" />
    <child
      link="FR_Hip" />
    <axis
      xyz="0 0 -1" />
  </joint>
  <link
    name="FR_Thigh">
    <inertial>
      <origin
        xyz="0.11253257794809 5.18368870619512E-07 -0.0213045756655169"
        rpy="0 0 0" />
      <mass
        value="0.248973034603016" />
      <inertia
        ixx="0.00019359900881667"
        ixy="-1.98376637994286E-08"
        ixz="2.90184454490922E-06"
        iyy="0.000199472018851969"
        iyz="1.17555634537835E-10"
        izz="0.000362587337502833" />
    </inertial>
    <visual>
      <origin
        xyz="0 0 0"
        rpy="0 0 0" />
      <geometry>
        <mesh
          filename="package://Biped/meshes/FR_Thigh.STL" />
      </geometry>
      <material
        name="">
        <color
          rgba="0.00784313725490196 0.23921568627451 0.823529411764706 1" />
      </material>
    </visual>
    <collision>
      <origin
        xyz="0 0 0"
        rpy="0 0 0" />
      <geometry>
        <mesh
          filename="package://Biped/meshes/FR_Thigh.STL" />
      </geometry>
    </collision>
  </link>
  <joint
    name="FR_J2"
    type="continuous">
    <origin
      xyz="-0.0700000000000002 0 0.045979703345944"
      rpy="3.14159265358979 -1.5707963267949 0" />
    <parent
      link="FR_Hip" />
    <child
      link="FR_Thigh" />
    <axis
      xyz="0 0 -1" />
  </joint>
  <link
    name="FR_Shin">
    <inertial>
      <origin
        xyz="0.110857092842009 1.65527585011954E-05 -0.00941299977249632"
        rpy="0 0 0" />
      <mass
        value="0.0687228409087856" />
      <inertia
        ixx="1.55422946691621E-05"
        ixy="6.46876984760074E-11"
        ixz="-1.18644635684239E-08"
        iyy="6.99945188679625E-05"
        iyz="-8.56742150772252E-09"
        izz="6.42198625809038E-05" />
    </inertial>
    <visual>
      <origin
        xyz="0 0 0"
        rpy="0 0 0" />
      <geometry>
        <mesh
          filename="package://Biped/meshes/FR_Shin.STL" />
      </geometry>
      <material
        name="">
        <color
          rgba="0.792156862745098 0.819607843137255 0.933333333333333 1" />
      </material>
    </visual>
    <collision>
      <origin
        xyz="0 0 0"
        rpy="0 0 0" />
      <geometry>
        <mesh
          filename="package://Biped/meshes/FR_Shin.STL" />
      </geometry>
    </collision>
  </link>
  <joint
    name="FR_J3"
    type="continuous">
    <origin
      xyz="0.318 0 0"
      rpy="0 0 0" />
    <parent
      link="FR_Thigh" />
    <child
      link="FR_Shin" />
    <axis
      xyz="0 0 1" />
  </joint>
  <link
    name="FL_Hip">
    <inertial>
      <origin
        xyz="-0.0192378662036579 -1.78144080875686E-08 0.0297489009840208"
        rpy="0 0 0" />
      <mass
        value="0.244991783639169" />
      <inertia
        ixx="0.000239714320229003"
        ixy="5.46133902679773E-12"
        ixz="-3.29715488209988E-12"
        iyy="0.000161925907771085"
        iyz="2.25080068580128E-10"
        izz="0.000229565612565153" />
    </inertial>
    <visual>
      <origin
        xyz="0 0 0"
        rpy="0 0 0" />
      <geometry>
        <mesh
          filename="package://Biped/meshes/FL_Hip.STL" />
      </geometry>
      <material
        name="">
        <color
          rgba="0.00784313725490196 0.23921568627451 0.823529411764706 1" />
      </material>
    </visual>
    <collision>
      <origin
        xyz="0 0 0"
        rpy="0 0 0" />
      <geometry>
        <mesh
          filename="package://Biped/meshes/FL_Hip.STL" />
      </geometry>
    </collision>
  </link>
  <joint
    name="FL_J1"
    type="fixed">
    <origin
      xyz="0.1 0.05 0.205567"
      rpy="0 0 -3.14159265358979" />
    <parent
      link="Body" />
    <child
      link="FL_Hip" />
    <axis
      xyz="0 0 0" />
  </joint>
  <link
    name="FL_Thigh">
    <inertial>
      <origin
        xyz="0.143513864618003 6.56602325482813E-07 -0.0218666576877556"
        rpy="0 0 0" />
      <mass
        value="0.17930787634648" />
      <inertia
        ixx="0.000138988786643332"
        ixy="-1.9486071828595E-08"
        ixz="2.17188845277477E-06"
        iyy="0.000148769435505882"
        iyz="1.23286174739105E-10"
        izz="0.000261542342004639" />
    </inertial>
    <visual>
      <origin
        xyz="0 0 0"
        rpy="0 0 0" />
      <geometry>
        <mesh
          filename="package://Biped/meshes/FL_Thigh.STL" />
      </geometry>
      <material
        name="">
        <color
          rgba="0.792156862745098 0.819607843137255 0.933333333333333 1" />
      </material>
    </visual>
    <collision>
      <origin
        xyz="0 0 0"
        rpy="0 0 0" />
      <geometry>
        <mesh
          filename="package://Biped/meshes/FL_Thigh.STL" />
      </geometry>
    </collision>
  </link>
  <joint
    name="FL_J2"
    type="continuous">
    <origin
      xyz="-0.0700000000000001 0 0.045979703345944"
      rpy="3.14159265358979 -1.5707963267949 0" />
    <parent
      link="FL_Hip" />
    <child
      link="FL_Thigh" />
    <axis
      xyz="0 0 -1" />
  </joint>
  <link
    name="FL_Shin">
    <inertial>
      <origin
        xyz="0.110857092842009 1.65527585012371E-05 -0.00941299977249625"
        rpy="0 0 0" />
      <mass
        value="0.0687228409087856" />
      <inertia
        ixx="1.55422946691621E-05"
        ixy="6.46876984714132E-11"
        ixz="-1.18644635684145E-08"
        iyy="6.99945188679625E-05"
        iyz="-8.56742150772119E-09"
        izz="6.42198625809038E-05" />
    </inertial>
    <visual>
      <origin
        xyz="0 0 0"
        rpy="0 0 0" />
      <geometry>
        <mesh
          filename="package://Biped/meshes/FL_Shin.STL" />
      </geometry>
      <material
        name="">
        <color
          rgba="0.792156862745098 0.819607843137255 0.933333333333333 1" />
      </material>
    </visual>
    <collision>
      <origin
        xyz="0 0 0"
        rpy="0 0 0" />
      <geometry>
        <mesh
          filename="package://Biped/meshes/FL_Shin.STL" />
      </geometry>
    </collision>
  </link>
  <joint
    name="FL_J3"
    type="continuous">
    <origin
      xyz="0.318 0 0"
      rpy="0 0 0" />
    <parent
      link="FL_Thigh" />
    <child
      link="FL_Shin" />
    <axis
      xyz="0 0 1" />
  </joint>
</robot>