<?xml version="1.0" encoding="utf-8"?>
<!-- This URDF was automatically created by SolidWorks to URDF Exporter! Originally created by Stephen Brawner (brawner@gmail.com) 
     Commit Version: 1.6.0-4-g7f85cfe  Build Version: 1.6.7995.38578
     For more information, please see http://wiki.ros.org/sw_urdf_exporter -->
<robot
  name="Biped">
  <link
    name="Body">
    <inertial>
      <origin
        xyz="0.00926528613176507 0.000699320108250356 0.0493143353044556"
        rpy="0 0 0" />
      <mass
        value="3.8947264825535" />
      <inertia
        ixx="0.0194955503823818"
        ixy="-1.24487671672811E-18"
        ixz="-3.49702720796586E-05"
        iyy="0.0158118089463474"
        iyz="4.50160129284462E-10"
        izz="0.0293272150469636" />
    </inertial>
    <visual>
      <origin
        xyz="0 0 0"
        rpy="0 0 0" />
      <geometry>
        <mesh
          filename="package://Biped/meshes/Body.STL" />
      </geometry>
      <material
        name="">
        <color
          rgba="0.286274509803922 0.662745098039216 0.329411764705882 1" />
      </material>
    </visual>
    <collision>
      <origin
        xyz="0 0 0"
        rpy="0 0 0" />
      <geometry>
        <mesh
          filename="package://Biped/meshes/Body.STL" />
      </geometry>
    </collision>
  </link>
  <link
    name="FR_Hip">
    <inertial>
      <origin
        xyz="-0.0192378662036592 -1.78144092255472E-08 0.0297489009840172"
        rpy="0 0 0" />
      <mass
        value="0.244991783639169" />
      <inertia
        ixx="0.000239714320228969"
        ixy="5.46133565970185E-12"
        ixz="-3.29715718020423E-12"
        iyy="0.000161925907771071"
        iyz="2.25080063692302E-10"
        izz="0.000229565612565133" />
    </inertial>
    <visual>
      <origin
        xyz="0 0 0"
        rpy="0 0 0" />
      <geometry>
        <mesh
          filename="package://Biped/meshes/FR_Hip.STL" />
      </geometry>
      <material
        name="">
        <color
          rgba="0.00784313725490196 0.23921568627451 0.823529411764706 1" />
      </material>
    </visual>
    <collision>
      <origin
        xyz="0 0 0"
        rpy="0 0 0" />
      <geometry>
        <mesh
          filename="package://Biped/meshes/FR_Hip.STL" />
      </geometry>
    </collision>
  </link>
  <joint
    name="FR_J1"
    type="continuous">
    <origin
      xyz="-0.00556699999999999 0.1 0.05"
      rpy="1.5707963267949 0 -1.5707963267949" />
    <parent
      link="Body" />
    <child
      link="FR_Hip" />
    <axis
      xyz="0 0 -1" />
  </joint>
  <link
    name="FR_Thigh">
    <inertial>
      <origin
        xyz="0.0987271588891257 5.23321424486523E-07 -0.021407803334963"
        rpy="0 0 0" />
      <mass
        value="0.246616840112861" />
      <inertia
        ixx="0.000193565727569503"
        ixy="-1.98376638264151E-08"
        ixz="2.90184454491069E-06"
        iyy="0.000162148965467049"
        iyz="1.1755562883534E-10"
        izz="0.000325264284117926" />
    </inertial>
    <visual>
      <origin
        xyz="0 0 0"
        rpy="0 0 0" />
      <geometry>
        <mesh
          filename="package://Biped/meshes/FR_Thigh.STL" />
      </geometry>
      <material
        name="">
        <color
          rgba="0.00784313725490196 0.23921568627451 0.823529411764706 1" />
      </material>
    </visual>
    <collision>
      <origin
        xyz="0 0 0"
        rpy="0 0 0" />
      <geometry>
        <mesh
          filename="package://Biped/meshes/FR_Thigh.STL" />
      </geometry>
    </collision>
  </link>
  <joint
    name="FR_J2"
    type="continuous">
    <origin
      xyz="-0.0700000000000002 0 0.045979703345944"
      rpy="3.14159265358979 -1.5707963267949 0" />
    <parent
      link="FR_Hip" />
    <child
      link="FR_Thigh" />
    <axis
      xyz="0 0 -1" />
  </joint>
  <link
    name="FR_Shin">
    <inertial>
      <origin
        xyz="-0.0264582429538076 1.71404259588503E-05 -0.00942766237548916"
        rpy="0 0 0" />
      <mass
        value="0.0663666464185938" />
      <inertia
        ixx="1.55090134219884E-05"
        ixy="6.46876985092399E-11"
        ixz="-1.18644635684153E-08"
        iyy="3.26714654829964E-05"
        iyz="-8.56742150772701E-09"
        izz="2.68968091959375E-05" />
    </inertial>
    <visual>
      <origin
        xyz="0 0 0"
        rpy="0 0 0" />
      <geometry>
        <mesh
          filename="package://Biped/meshes/FR_Shin.STL" />
      </geometry>
      <material
        name="">
        <color
          rgba="0.792156862745098 0.819607843137255 0.933333333333333 1" />
      </material>
    </visual>
    <collision>
      <origin
        xyz="0 0 0"
        rpy="0 0 0" />
      <geometry>
        <mesh
          filename="package://Biped/meshes/FR_Shin.STL" />
      </geometry>
    </collision>
  </link>
  <joint
    name="FR_J3"
    type="continuous">
    <origin
      xyz="0.318 0 0"
      rpy="0 0 0" />
    <parent
      link="FR_Thigh" />
    <child
      link="FR_Shin" />
    <axis
      xyz="0 0 1" />
  </joint>
  <link
    name="FL_Hip">
    <inertial>
      <origin
        xyz="-0.0192378662036592 -1.78144092533028E-08 0.0297489009840172"
        rpy="0 0 0" />
      <mass
        value="0.244991783639169" />
      <inertia
        ixx="0.000239714320228969"
        ixy="5.4613356181622E-12"
        ixz="-3.29715723314003E-12"
        iyy="0.00016192590777107"
        iyz="2.25080063683702E-10"
        izz="0.000229565612565132" />
    </inertial>
    <visual>
      <origin
        xyz="0 0 0"
        rpy="0 0 0" />
      <geometry>
        <mesh
          filename="package://Biped/meshes/FL_Hip.STL" />
      </geometry>
      <material
        name="">
        <color
          rgba="0.00784313725490196 0.23921568627451 0.823529411764706 1" />
      </material>
    </visual>
    <collision>
      <origin
        xyz="0 0 0"
        rpy="0 0 0" />
      <geometry>
        <mesh
          filename="package://Biped/meshes/FL_Hip.STL" />
      </geometry>
    </collision>
  </link>
  <joint
    name="FL_J1"
    type="fixed">
    <origin
      xyz="-0.005567 -0.1 0.05"
      rpy="-1.5708 0 1.5708" />
    <parent
      link="Body" />
    <child
      link="FL_Hip" />
    <axis
      xyz="0 0 0" />
  </joint>
  <link
    name="FL_Thigh">
    <inertial>
      <origin
        xyz="0.124685838498925 6.65345322281574E-07 -0.0220180100565705"
        rpy="0 0 0" />
      <mass
        value="0.176951681856318" />
      <inertia
        ixx="0.000138955505396163"
        ixy="-1.94860718536006E-08"
        ixz="2.17188845277633E-06"
        iyy="0.000111446382120958"
        iyz="1.23286168873184E-10"
        izz="0.000224219288619725" />
    </inertial>
    <visual>
      <origin
        xyz="0 0 0"
        rpy="0 0 0" />
      <geometry>
        <mesh
          filename="package://Biped/meshes/FL_Thigh.STL" />
      </geometry>
      <material
        name="">
        <color
          rgba="0.792156862745098 0.819607843137255 0.933333333333333 1" />
      </material>
    </visual>
    <collision>
      <origin
        xyz="0 0 0"
        rpy="0 0 0" />
      <geometry>
        <mesh
          filename="package://Biped/meshes/FL_Thigh.STL" />
      </geometry>
    </collision>
  </link>
  <joint
    name="FL_J2"
    type="continuous">
    <origin
      xyz="-0.07 0 0.04598"
      rpy="3.1416 -1.5708 0" />
    <parent
      link="FL_Hip" />
    <child
      link="FL_Thigh" />
    <axis
      xyz="0 0 -1" />
  </joint>
  <link
    name="FL_Shin">
    <inertial>
      <origin
        xyz="-0.026458 1.714E-05 -0.0094277"
        rpy="0 0 0" />
      <mass
        value="0.066367" />
      <inertia
        ixx="1.5509E-05"
        ixy="6.4688E-11"
        ixz="-1.1864E-08"
        iyy="3.2671E-05"
        iyz="-8.5674E-09"
        izz="2.6897E-05" />
    </inertial>
    <visual>
      <origin
        xyz="0 0 0"
        rpy="0 0 0" />
      <geometry>
        <mesh
          filename="package://Biped/meshes/FL_Shin.STL" />
      </geometry>
      <material
        name="">
        <color
          rgba="0.79216 0.81961 0.93333 1" />
      </material>
    </visual>
    <collision>
      <origin
        xyz="0 0 0"
        rpy="0 0 0" />
      <geometry>
        <mesh
          filename="package://Biped/meshes/FL_Shin.STL" />
      </geometry>
    </collision>
  </link>
  <joint
    name="FL_J3"
    type="continuous">
    <origin
      xyz="0.318 0 0"
      rpy="0 0 0" />
    <parent
      link="FL_Thigh" />
    <child
      link="FL_Shin" />
    <axis
      xyz="0 0 1" />
  </joint>
  <link
    name="ReactionWheelX">
    <inertial>
      <origin
        xyz="0 2.7756E-17 1.3878E-17"
        rpy="0 0 0" />
      <mass
        value="0.097845" />
      <inertia
        ixx="0.00023479"
        ixy="-3.0975E-21"
        ixz="3.9219E-23"
        iyy="0.0001185"
        iyz="1.852E-20"
        izz="0.0001185" />
    </inertial>
    <visual>
      <origin
        xyz="0 0 0"
        rpy="0 0 0" />
      <geometry>
        <mesh
          filename="package://Biped/meshes/ReactionWheelX.STL" />
      </geometry>
      <material
        name="">
        <color
          rgba="0.79216 0.81961 0.93333 1" />
      </material>
    </visual>
    <collision>
      <origin
        xyz="0 0 0"
        rpy="0 0 0" />
      <geometry>
        <mesh
          filename="package://Biped/meshes/ReactionWheelX.STL" />
      </geometry>
    </collision>
  </link>
  <joint
    name="WheelX"
    type="continuous">
    <origin
      xyz="-0.07 0 0.05"
      rpy="0 0 0" />
    <parent
      link="Body" />
    <child
      link="ReactionWheelX" />
    <axis
      xyz="1 0 0" />
  </joint>
  <link
    name="ReactionWheelY">
    <inertial>
      <origin
        xyz="0 2.7756E-17 0"
        rpy="0 0 0" />
      <mass
        value="0.097845" />
      <inertia
        ixx="0.0001185"
        ixy="-4.9598E-21"
        ixz="-3.4289E-20"
        iyy="0.00023479"
        iyz="1.5862E-21"
        izz="0.0001185" />
    </inertial>
    <visual>
      <origin
        xyz="0 0 0"
        rpy="0 0 0" />
      <geometry>
        <mesh
          filename="package://Biped/meshes/ReactionWheelY.STL" />
      </geometry>
      <material
        name="">
        <color
          rgba="0.79216 0.81961 0.93333 1" />
      </material>
    </visual>
    <collision>
      <origin
        xyz="0 0 0"
        rpy="0 0 0" />
      <geometry>
        <mesh
          filename="package://Biped/meshes/ReactionWheelY.STL" />
      </geometry>
    </collision>
  </link>
  <joint
    name="WheelY"
    type="continuous">
    <origin
      xyz="0.020147 0 0.05"
      rpy="0 0 0" />
    <parent
      link="Body" />
    <child
      link="ReactionWheelY" />
    <axis
      xyz="0 1 0" />
  </joint>
</robot>