<?xml version="1.0" encoding="utf-8"?>
<!-- This URDF was automatically created by SolidWorks to URDF Exporter! Originally created by Stephen Brawner (brawner@gmail.com) 
     Commit Version: 1.6.0-4-g7f85cfe  Build Version: 1.6.7995.38578
     For more information, please see http://wiki.ros.org/sw_urdf_exporter -->
<robot
  name="TorquePole">
  <link
    name="base_link">
    <inertial>
      <origin
        xyz="-0.083998 0.021329 1.1398E-07"
        rpy="0 0 0" />
      <mass
        value="0.21781" />
      <inertia
        ixx="0.00019789"
        ixy="-4.4706E-06"
        ixz="1.392E-09"
        iyy="0.00035902"
        iyz="-1.2927E-10"
        izz="0.0002038" />
    </inertial>
    <visual>
      <origin
        xyz="0 0 0"
        rpy="0 0 0" />
      <geometry>
        <mesh
          filename="package://TorquePole/meshes/base_link.STL" />
      </geometry>
      <material
        name="">
        <color
          rgba="0.77647 0.75686 0.73725 1" />
      </material>
    </visual>
    <collision>
      <origin
        xyz="0 0 0"
        rpy="0 0 0" />
      <geometry>
        <mesh
          filename="package://TorquePole/meshes/base_link.STL" />
      </geometry>
    </collision>
  </link>
  <link
    name="pendulum">
    <inertial>
      <origin
        xyz="-6.9927E-06 0.0017849 -0.11081"
        rpy="0 0 0" />
      <mass
        value="0.068723" />
      <inertia
        ixx="6.9994E-05"
        ixy="-3.6193E-09"
        ixz="-3.2692E-11"
        iyy="6.422E-05"
        iyz="1.418E-08"
        izz="1.5542E-05" />
    </inertial>
    <visual>
      <origin
        xyz="0 0 0"
        rpy="0 0 0" />
      <geometry>
        <mesh
          filename="package://TorquePole/meshes/pendulum.STL" />
      </geometry>
      <material
        name="">
        <color
          rgba="0.79216 0.81961 0.93333 1" />
      </material>
    </visual>
    <collision>
      <origin
        xyz="0 0 0"
        rpy="0 0 0" />
      <geometry>
        <mesh
          filename="package://TorquePole/meshes/pendulum.STL" />
      </geometry>
    </collision>
  </link>
  <joint
    name="PullyJoint"
    type="revolute">
    <origin
      xyz="-0.318 0.025 0"
      rpy="0 0 0" />
    <parent
      link="base_link" />
    <child
      link="pendulum" />
    <axis
      xyz="0 1 0" />
    <limit
      lower="6.28"
      upper="-1.57"
      effort="3"
      velocity="300" />
  </joint>
</robot>