<?xml version="1.0" encoding="utf-8"?>
<!-- This URDF was automatically created by SolidWorks to URDF Exporter! Originally created by Stephen Brawner (brawner@gmail.com) 
     Commit Version: 1.6.0-4-g7f85cfe  Build Version: 1.6.7995.38578
     For more information, please see http://wiki.ros.org/sw_urdf_exporter -->
<robot
  name="TorquePole">
  <link
    name="base_link">
    <inertial>
      <origin
        xyz="0.00473504106989386 -9.50489592796422E-08 0.0291987104263197"
        rpy="0 0 0" />
      <mass
        value="0.130519789197275" />
      <inertia
        ixx="8.70641803002097E-05"
        ixy="-1.19287125339871E-09"
        ixz="-2.17105317141525E-06"
        iyy="0.000324093310822791"
        iyz="2.86980327042066E-10"
        izz="0.0003869376807318" />
    </inertial>
    <visual>
      <origin
        xyz="0 0 0"
        rpy="0 0 0" />
      <geometry>
        <mesh
          filename="../meshes/base_link.STL" />
      </geometry>
      <material
        name="">
        <color
          rgba="0.792156862745098 0.819607843137255 0.933333333333333 1" />
      </material>
    </visual>
    <collision>
      <origin
        xyz="0 0 0"
        rpy="0 0 0" />
      <geometry>
        <mesh
          filename="../meshes/base_link.STL" />
      </geometry>
    </collision>
  </link>
  <link
    name="pendulum_link">
    <inertial>
      <origin
        xyz="2.4558E-11 -0.3727 0.061834"
        rpy="0 0 0" />
      <mass
        value="0.091873" />
      <inertia
        ixx="0.00014248"
        ixy="-6.8173E-09"
        ixz="-4.9901E-14"
        iyy="1.9585E-05"
        iyz="-1.9833E-08"
        izz="0.00014431" />
    </inertial>
    <visual>
      <origin
        xyz="0 0 0"
        rpy="0 0 0" />
      <geometry>
        <mesh
          filename="../meshes/pendulum_link.STL" />
      </geometry>
      <material
        name="">
        <color
          rgba="0.79216 0.81961 0.93333 1" />
      </material>
    </visual>
    <collision>
      <origin
        xyz="0 0 0"
        rpy="0 0 0" />
      <geometry>
        <mesh
          filename="../meshes/pendulum_link.STL" />
      </geometry>
    </collision>
  </link>
  <joint
    name="pendulum"
    type="continuous">
    <origin
      xyz="0 0 0"
      rpy="0 0 0" />
    <parent
      link="base_link" />
    <child
      link="pendulum_link" />
    <axis
      xyz="0 0 -1" />
    <limit
      effort="0.5"
      velocity="3000" />
  </joint>
</robot>