<?xml version="1.0" encoding="utf-8"?>
<!-- This URDF was automatically created by SolidWorks to URDF Exporter! Originally created by Stephen Brawner (brawner@gmail.com) 
     Commit Version: 1.6.0-4-g7f85cfe  Build Version: 1.6.7995.38578
     For more information, please see http://wiki.ros.org/sw_urdf_exporter -->
<robot
  name="TorquePole">
  <link
    name="base_link">
    <inertial>
      <origin
        xyz="0.0074761 -0.0057066 0.031484"
        rpy="0 0 0" />
      <mass
        value="0.18536" />
      <inertia
        ixx="0.00015776"
        ixy="-1.1929E-09"
        ixz="-2.1711E-06"
        iyy="0.00033622"
        iyz="-6.8647E-06"
        izz="0.0004492" />
    </inertial>
    <visual>
      <origin
        xyz="0 0 0"
        rpy="0 0 0" />
      <geometry>
        <mesh
          filename="../meshes/base_link.STL" />
      </geometry>
      <material
        name="">
        <color
          rgba="0.79216 0.81961 0.93333 1" />
      </material>
    </visual>
    <collision>
      <origin
        xyz="0 0 0"
        rpy="0 0 0" />
      <geometry>
        <mesh
          filename="../meshes/base_link.STL" />
      </geometry>
    </collision>
  </link>
  <link
    name="pendulum_link">
    <inertial>
      <origin
        xyz="9.7897E-11 0.39044 0.062361"
        rpy="0 0 0" />
      <mass
        value="0.098923" />
      <inertia
        ixx="0.00015022"
        ixy="-7.662E-09"
        ixz="1.0427E-11"
        iyy="3.4932E-05"
        iyz="1.9833E-08"
        izz="0.0001807" />
    </inertial>
    <visual>
      <origin
        xyz="0 0 0"
        rpy="0 0 0" />
      <geometry>
        <mesh
          filename="../meshes/pendulum_link.STL" />
      </geometry>
      <material
        name="">
        <color
          rgba="0.79216 0.81961 0.93333 1" />
      </material>
    </visual>
    <collision>
      <origin
        xyz="0 0 0"
        rpy="0 0 0" />
      <geometry>
        <mesh
          filename="../meshes/pendulum_link.STL" />
      </geometry>
    </collision>
  </link>
  <joint
    name="pendulum"
    type="continuous">
    <origin
      xyz="0 0 0"
      rpy="0 0 0" />
    <parent
      link="base_link" />
    <child
      link="pendulum_link" />
    <axis
      xyz="0 0 -1" />
    <limit
      effort="0.5"
      velocity="3000" />
  </joint>
</robot>