<?xml version="1.0" encoding="utf-8"?>
<!-- This URDF was automatically created by SolidWorks to URDF Exporter! Originally created by Stephen Brawner (brawner@gmail.com) 
     Commit Version: 1.6.0-4-g7f85cfe  Build Version: 1.6.7995.38578
     For more information, please see http://wiki.ros.org/sw_urdf_exporter -->
<robot
  name="Quad_Foot">
  <link
    name="Body">
    <inertial>
      <origin
        xyz="1.66533453693773E-16 0.0494666684847991 -0.000433806407116308"
        rpy="0 0 0" />
      <mass
        value="7.8723215089476" />
      <inertia
        ixx="0.0615804330234304"
        ixy="-2.01949764644171E-18"
        ixz="-6.46491866239123E-19"
        iyy="0.0969437093098223"
        iyz="0.000155611639535358"
        izz="0.0465442944559655" />
    </inertial>
    <visual>
      <origin
        xyz="0 0 0"
        rpy="0 0 0" />
      <geometry>
        <mesh
          filename="package://Quad_Foot/meshes/Body.STL" />
      </geometry>
      <material
        name="">
        <color
          rgba="0.286274509803922 0.662745098039216 0.329411764705882 1" />
      </material>
    </visual>
    <collision>
      <origin
        xyz="0 0 0"
        rpy="0 0 0" />
      <geometry>
        <mesh
          filename="package://Quad_Foot/meshes/Body.STL" />
      </geometry>
    </collision>
  </link>
  <link
    name="FR_Hip">
    <inertial>
      <origin
        xyz="-0.0192378662036615 -1.78144099749478E-08 0.0297489009840162"
        rpy="0 0 0" />
      <mass
        value="0.244991783639187" />
      <inertia
        ixx="0.000239714320228986"
        ixy="5.46133418222247E-12"
        ixz="-3.29715836847982E-12"
        iyy="0.000161925907771085"
        iyz="2.25080068085063E-10"
        izz="0.000229565612565136" />
    </inertial>
    <visual>
      <origin
        xyz="0 0 0"
        rpy="0 0 0" />
      <geometry>
        <mesh
          filename="package://Quad_Foot/meshes/FR_Hip.STL" />
      </geometry>
      <material
        name="">
        <color
          rgba="0.00784313725490196 0.23921568627451 0.823529411764706 1" />
      </material>
    </visual>
    <collision>
      <origin
        xyz="0 0 0"
        rpy="0 0 0" />
      <geometry>
        <mesh
          filename="package://Quad_Foot/meshes/FR_Hip.STL" />
      </geometry>
    </collision>
  </link>
  <joint
    name="FR_J1"
    type="revolute">
    <origin
      xyz="-0.1 0.05 0.205567"
      rpy="0 0 0" />
    <parent
      link="Body" />
    <child
      link="FR_Hip" />
    <axis
      xyz="0 0 -1" />
    <limit
      lower="0"
      upper="0"
      effort="0"
      velocity="0" />
  </joint>
  <link
    name="FR_Thigh">
    <inertial>
      <origin
        xyz="0.0213045756655135 5.18368892268861E-07 0.112532577948084"
        rpy="0 0 0" />
      <mass
        value="0.248973034603068" />
      <inertia
        ixx="0.000362587337502919"
        ixy="-1.17555629123786E-10"
        ixz="-2.90184454491022E-06"
        iyy="0.000199472018852034"
        iyz="-1.98376638240401E-08"
        izz="0.00019359900881669" />
    </inertial>
    <visual>
      <origin
        xyz="0 0 0"
        rpy="0 0 0" />
      <geometry>
        <mesh
          filename="package://Quad_Foot/meshes/FR_Thigh.STL" />
      </geometry>
      <material
        name="">
        <color
          rgba="0.00784313725490196 0.23921568627451 0.823529411764706 1" />
      </material>
    </visual>
    <collision>
      <origin
        xyz="0 0 0"
        rpy="0 0 0" />
      <geometry>
        <mesh
          filename="package://Quad_Foot/meshes/FR_Thigh.STL" />
      </geometry>
    </collision>
  </link>
  <joint
    name="FR_J2"
    type="continuous">
    <origin
      xyz="-0.0700000000000002 0 0.045979703345944"
      rpy="0 0 0" />
    <parent
      link="FR_Hip" />
    <child
      link="FR_Thigh" />
    <axis
      xyz="1 0 0" />
  </joint>
  <link
    name="FR_Shin">
    <inertial>
      <origin
        xyz="0.00959832456303467 2.39804538812033E-05 0.0260265273890261"
        rpy="0 0 0" />
      <mass
        value="0.0474366579848811" />
      <inertia
        ixx="6.28828414871736E-05"
        ixy="8.5674215077243E-09"
        ixz="1.18644635684174E-08"
        iyy="6.08592895237621E-05"
        iyz="6.46876985462408E-11"
        izz="6.94013659390262E-06" />
    </inertial>
    <visual>
      <origin
        xyz="0 0 0"
        rpy="0 0 0" />
      <geometry>
        <mesh
          filename="package://Quad_Foot/meshes/FR_Shin.STL" />
      </geometry>
      <material
        name="">
        <color
          rgba="0.792156862745098 0.819607843137255 0.933333333333333 1" />
      </material>
    </visual>
    <collision>
      <origin
        xyz="0 0 0"
        rpy="0 0 0" />
      <geometry>
        <mesh
          filename="package://Quad_Foot/meshes/FR_Shin.STL" />
      </geometry>
    </collision>
  </link>
  <joint
    name="FR_J3"
    type="continuous">
    <origin
      xyz="0 0 0.318"
      rpy="0 0 0" />
    <parent
      link="FR_Thigh" />
    <child
      link="FR_Shin" />
    <axis
      xyz="-1 0 0" />
  </joint>
  <link
    name="FR_Foot">
    <inertial>
      <origin
        xyz="5.55111512312578E-17 0 -0.00859640058408673"
        rpy="0 0 0" />
      <mass
        value="0.0212861829239045" />
      <inertia
        ixx="1.33702109373009E-06"
        ixy="3.8534806819522E-21"
        ixz="4.19056804094644E-22"
        iyy="9.13522934420036E-06"
        iyz="6.90340370422902E-22"
        izz="8.60215807525945E-06" />
    </inertial>
    <visual>
      <origin
        xyz="0 0 0"
        rpy="0 0 0" />
      <geometry>
        <mesh
          filename="package://Quad_Foot/meshes/FR_Foot.STL" />
      </geometry>
      <material
        name="">
        <color
          rgba="0.286274509803922 0.662745098039216 0.329411764705882 1" />
      </material>
    </visual>
    <collision>
      <origin
        xyz="0 0 0"
        rpy="0 0 0" />
      <geometry>
        <mesh
          filename="package://Quad_Foot/meshes/FR_Foot.STL" />
      </geometry>
    </collision>
  </link>
  <joint
    name="FR_J4"
    type="fixed">
    <origin
      xyz="0.0089999999999999 0 0.3085"
      rpy="0 0 0" />
    <parent
      link="FR_Shin" />
    <child
      link="FR_Foot" />
    <axis
      xyz="0 0 0" />
  </joint>
  <link
    name="FL_Hip">
    <inertial>
      <origin
        xyz="0.0192378662036614 1.78144100027033E-08 0.0297489009840162"
        rpy="0 0 0" />
      <mass
        value="0.244991783639187" />
      <inertia
        ixx="0.000239714320228986"
        ixy="5.46133417331164E-12"
        ixz="3.29715838086681E-12"
        iyy="0.000161925907771085"
        iyz="-2.25080068067518E-10"
        izz="0.000229565612565136" />
    </inertial>
    <visual>
      <origin
        xyz="0 0 0"
        rpy="0 0 0" />
      <geometry>
        <mesh
          filename="package://Quad_Foot/meshes/FL_Hip.STL" />
      </geometry>
      <material
        name="">
        <color
          rgba="0.00784313725490196 0.23921568627451 0.823529411764706 1" />
      </material>
    </visual>
    <collision>
      <origin
        xyz="0 0 0"
        rpy="0 0 0" />
      <geometry>
        <mesh
          filename="package://Quad_Foot/meshes/FL_Hip.STL" />
      </geometry>
    </collision>
  </link>
  <joint
    name="FL_J1"
    type="revolute">
    <origin
      xyz="0.1 0.05 0.205567"
      rpy="0 0 0" />
    <parent
      link="Body" />
    <child
      link="FL_Hip" />
    <axis
      xyz="0 0 -1" />
    <limit
      lower="0"
      upper="0"
      effort="0"
      velocity="0" />
  </joint>
  <link
    name="FL_Thigh">
    <inertial>
      <origin
        xyz="-0.0189308933438334 -5.55471749583147E-07 0.112857002495052"
        rpy="0 0 0" />
      <mass
        value="0.232342826148228" />
      <inertia
        ixx="0.000352781899754072"
        ixy="-1.17555629062216E-10"
        ixz="2.90184454491025E-06"
        iyy="0.000194519426806648"
        iyz="1.98376638239623E-08"
        izz="0.000188646416771304" />
    </inertial>
    <visual>
      <origin
        xyz="0 0 0"
        rpy="0 0 0" />
      <geometry>
        <mesh
          filename="package://Quad_Foot/meshes/FL_Thigh.STL" />
      </geometry>
      <material
        name="">
        <color
          rgba="0.792156862745098 0.819607843137255 0.933333333333333 1" />
      </material>
    </visual>
    <collision>
      <origin
        xyz="0 0 0"
        rpy="0 0 0" />
      <geometry>
        <mesh
          filename="package://Quad_Foot/meshes/FL_Thigh.STL" />
      </geometry>
    </collision>
  </link>
  <joint
    name="FL_J2"
    type="continuous">
    <origin
      xyz="0.0700000000000002 0 0.045979703345944"
      rpy="0 0 0" />
    <parent
      link="FL_Hip" />
    <child
      link="FL_Thigh" />
    <axis
      xyz="-1 0 0" />
  </joint>
  <link
    name="FL_Shin">
    <inertial>
      <origin
        xyz="-0.00959832456303457 -2.39804538812588E-05 0.0260265273890262"
        rpy="0 0 0" />
      <mass
        value="0.0474366579848811" />
      <inertia
        ixx="6.28828414871736E-05"
        ixy="8.56742150772414E-09"
        ixz="-1.18644635684154E-08"
        iyy="6.08592895237621E-05"
        iyz="-6.4687698544587E-11"
        izz="6.94013659390262E-06" />
    </inertial>
    <visual>
      <origin
        xyz="0 0 0"
        rpy="0 0 0" />
      <geometry>
        <mesh
          filename="package://Quad_Foot/meshes/FL_Shin.STL" />
      </geometry>
      <material
        name="">
        <color
          rgba="0.792156862745098 0.819607843137255 0.933333333333333 1" />
      </material>
    </visual>
    <collision>
      <origin
        xyz="0 0 0"
        rpy="0 0 0" />
      <geometry>
        <mesh
          filename="package://Quad_Foot/meshes/FL_Shin.STL" />
      </geometry>
    </collision>
  </link>
  <joint
    name="FL_J3"
    type="continuous">
    <origin
      xyz="0 0 0.318"
      rpy="0 0 0" />
    <parent
      link="FL_Thigh" />
    <child
      link="FL_Shin" />
    <axis
      xyz="1 0 0" />
  </joint>
  <link
    name="FL_Foot">
    <inertial>
      <origin
        xyz="-1.38777878078145E-17 0 -0.00859640058408684"
        rpy="0 0 0" />
      <mass
        value="0.0212861829239045" />
      <inertia
        ixx="1.33702109373009E-06"
        ixy="1.70933528643976E-21"
        ixz="-1.85209765088032E-22"
        iyy="9.13522934420037E-06"
        iyz="-4.76200764720447E-22"
        izz="8.60215807525945E-06" />
    </inertial>
    <visual>
      <origin
        xyz="0 0 0"
        rpy="0 0 0" />
      <geometry>
        <mesh
          filename="package://Quad_Foot/meshes/FL_Foot.STL" />
      </geometry>
      <material
        name="">
        <color
          rgba="0.286274509803922 0.662745098039216 0.329411764705882 1" />
      </material>
    </visual>
    <collision>
      <origin
        xyz="0 0 0"
        rpy="0 0 0" />
      <geometry>
        <mesh
          filename="package://Quad_Foot/meshes/FL_Foot.STL" />
      </geometry>
    </collision>
  </link>
  <joint
    name="FL_J4"
    type="fixed">
    <origin
      xyz="-0.00899999999999995 0 0.3085"
      rpy="0 0 0" />
    <parent
      link="FL_Shin" />
    <child
      link="FL_Foot" />
    <axis
      xyz="0 0 0" />
  </joint>
  <link
    name="BR_Hip">
    <inertial>
      <origin
        xyz="-0.0192378662036614 1.78144099333144E-08 -0.0297489009840162"
        rpy="0 0 0" />
      <mass
        value="0.244991783639187" />
      <inertia
        ixx="0.000239714320228986"
        ixy="-5.46133413156008E-12"
        ixz="3.2971583652978E-12"
        iyy="0.000161925907771085"
        iyz="2.25080068064432E-10"
        izz="0.000229565612565136" />
    </inertial>
    <visual>
      <origin
        xyz="0 0 0"
        rpy="0 0 0" />
      <geometry>
        <mesh
          filename="package://Quad_Foot/meshes/BR_Hip.STL" />
      </geometry>
      <material
        name="">
        <color
          rgba="0.00784313725490196 0.23921568627451 0.823529411764706 1" />
      </material>
    </visual>
    <collision>
      <origin
        xyz="0 0 0"
        rpy="0 0 0" />
      <geometry>
        <mesh
          filename="package://Quad_Foot/meshes/BR_Hip.STL" />
      </geometry>
    </collision>
  </link>
  <joint
    name="BR_J1"
    type="revolute">
    <origin
      xyz="-0.1 0.0500000000000001 -0.205567"
      rpy="0 0 0" />
    <parent
      link="Body" />
    <child
      link="BR_Hip" />
    <axis
      xyz="0 0 1" />
    <limit
      lower="0"
      upper="0"
      effort="0"
      velocity="0" />
  </joint>
  <link
    name="BR_Thigh">
    <inertial>
      <origin
        xyz="0.0189308933438333 -5.55471749541514E-07 -0.112857002495052"
        rpy="0 0 0" />
      <mass
        value="0.232342826148228" />
      <inertia
        ixx="0.000352781899754072"
        ixy="1.17555629151467E-10"
        ixz="2.9018445449102E-06"
        iyy="0.000194519426806648"
        iyz="-1.98376638238884E-08"
        izz="0.000188646416771305" />
    </inertial>
    <visual>
      <origin
        xyz="0 0 0"
        rpy="0 0 0" />
      <geometry>
        <mesh
          filename="package://Quad_Foot/meshes/BR_Thigh.STL" />
      </geometry>
      <material
        name="">
        <color
          rgba="0.792156862745098 0.819607843137255 0.933333333333333 1" />
      </material>
    </visual>
    <collision>
      <origin
        xyz="0 0 0"
        rpy="0 0 0" />
      <geometry>
        <mesh
          filename="package://Quad_Foot/meshes/BR_Thigh.STL" />
      </geometry>
    </collision>
  </link>
  <joint
    name="BR_J2"
    type="continuous">
    <origin
      xyz="-0.0700000000000003 0 -0.045979703345944"
      rpy="0 0 0" />
    <parent
      link="BR_Hip" />
    <child
      link="BR_Thigh" />
    <axis
      xyz="1 0 0" />
  </joint>
  <link
    name="BR_Shin">
    <inertial>
      <origin
        xyz="0.00959832456303455 -2.39804538812449E-05 -0.026026527389026"
        rpy="0 0 0" />
      <mass
        value="0.0474366579848811" />
      <inertia
        ixx="6.28828414871737E-05"
        ixy="-8.56742150772364E-09"
        ixz="-1.18644635684181E-08"
        iyy="6.08592895237622E-05"
        iyz="6.46876985464709E-11"
        izz="6.94013659390262E-06" />
    </inertial>
    <visual>
      <origin
        xyz="0 0 0"
        rpy="0 0 0" />
      <geometry>
        <mesh
          filename="package://Quad_Foot/meshes/BR_Shin.STL" />
      </geometry>
      <material
        name="">
        <color
          rgba="0.792156862745098 0.819607843137255 0.933333333333333 1" />
      </material>
    </visual>
    <collision>
      <origin
        xyz="0 0 0"
        rpy="0 0 0" />
      <geometry>
        <mesh
          filename="package://Quad_Foot/meshes/BR_Shin.STL" />
      </geometry>
    </collision>
  </link>
  <joint
    name="BR_J3"
    type="continuous">
    <origin
      xyz="0 0 -0.318"
      rpy="0 0 0" />
    <parent
      link="BR_Thigh" />
    <child
      link="BR_Shin" />
    <axis
      xyz="-1 0 0" />
  </joint>
  <link
    name="BR_Foot">
    <inertial>
      <origin
        xyz="5.55111512312578E-17 0 0.00859640058408673"
        rpy="0 0 0" />
      <mass
        value="0.0212861829239045" />
      <inertia
        ixx="1.33702109373009E-06"
        ixy="-4.38236929229019E-21"
        ixz="-4.73923263324219E-22"
        iyy="9.13522934420038E-06"
        iyz="4.77619493866767E-22"
        izz="8.60215807525947E-06" />
    </inertial>
    <visual>
      <origin
        xyz="0 0 0"
        rpy="0 0 0" />
      <geometry>
        <mesh
          filename="package://Quad_Foot/meshes/BR_Foot.STL" />
      </geometry>
      <material
        name="">
        <color
          rgba="0.286274509803922 0.662745098039216 0.329411764705882 1" />
      </material>
    </visual>
    <collision>
      <origin
        xyz="0 0 0"
        rpy="0 0 0" />
      <geometry>
        <mesh
          filename="package://Quad_Foot/meshes/BR_Foot.STL" />
      </geometry>
    </collision>
  </link>
  <joint
    name="BR_J4"
    type="fixed">
    <origin
      xyz="0.00900000000000001 0 -0.3085"
      rpy="0 0 0" />
    <parent
      link="BR_Shin" />
    <child
      link="BR_Foot" />
    <axis
      xyz="0 0 0" />
  </joint>
  <link
    name="BL_Hip">
    <inertial>
      <origin
        xyz="0.0192378662036614 -1.78144100443367E-08 -0.0297489009840163"
        rpy="0 0 0" />
      <mass
        value="0.244991783639187" />
      <inertia
        ixx="0.000239714320228986"
        ixy="-5.46133415456406E-12"
        ixz="-3.29715835968541E-12"
        iyy="0.000161925907771085"
        iyz="-2.25080068061364E-10"
        izz="0.000229565612565136" />
    </inertial>
    <visual>
      <origin
        xyz="0 0 0"
        rpy="0 0 0" />
      <geometry>
        <mesh
          filename="package://Quad_Foot/meshes/BL_Hip.STL" />
      </geometry>
      <material
        name="">
        <color
          rgba="0.00784313725490196 0.23921568627451 0.823529411764706 1" />
      </material>
    </visual>
    <collision>
      <origin
        xyz="0 0 0"
        rpy="0 0 0" />
      <geometry>
        <mesh
          filename="package://Quad_Foot/meshes/BL_Hip.STL" />
      </geometry>
    </collision>
  </link>
  <joint
    name="BL_J1"
    type="revolute">
    <origin
      xyz="0.1 0.05 -0.205567"
      rpy="0 0 0" />
    <parent
      link="Body" />
    <child
      link="BL_Hip" />
    <axis
      xyz="0 0 1" />
    <limit
      lower="0"
      upper="0"
      effort="0"
      velocity="0" />
  </joint>
  <link
    name="BL_Thigh">
    <inertial>
      <origin
        xyz="-0.0213045756655136 5.18368892185594E-07 -0.112532577948083"
        rpy="0 0 0" />
      <mass
        value="0.248973034603069" />
      <inertia
        ixx="0.00036258733750292"
        ixy="1.1755562914981E-10"
        ixz="-2.90184454491026E-06"
        iyy="0.000199472018852034"
        iyz="1.98376638237457E-08"
        izz="0.000193599008816691" />
    </inertial>
    <visual>
      <origin
        xyz="0 0 0"
        rpy="0 0 0" />
      <geometry>
        <mesh
          filename="package://Quad_Foot/meshes/BL_Thigh.STL" />
      </geometry>
      <material
        name="">
        <color
          rgba="0.00784313725490196 0.23921568627451 0.823529411764706 1" />
      </material>
    </visual>
    <collision>
      <origin
        xyz="0 0 0"
        rpy="0 0 0" />
      <geometry>
        <mesh
          filename="package://Quad_Foot/meshes/BL_Thigh.STL" />
      </geometry>
    </collision>
  </link>
  <joint
    name="BL_J2"
    type="continuous">
    <origin
      xyz="0.0700000000000002 0 -0.045979703345944"
      rpy="0 0 0" />
    <parent
      link="BL_Hip" />
    <child
      link="BL_Thigh" />
    <axis
      xyz="-1 0 0" />
  </joint>
  <link
    name="BL_Shin">
    <inertial>
      <origin
        xyz="-0.0095983245630346 2.39804538812588E-05 -0.0260265273890262"
        rpy="0 0 0" />
      <mass
        value="0.047436657984881" />
      <inertia
        ixx="6.28828414871737E-05"
        ixy="-8.56742150772526E-09"
        ixz="1.18644635684169E-08"
        iyy="6.08592895237622E-05"
        iyz="-6.46876985458909E-11"
        izz="6.94013659390261E-06" />
    </inertial>
    <visual>
      <origin
        xyz="0 0 0"
        rpy="0 0 0" />
      <geometry>
        <mesh
          filename="package://Quad_Foot/meshes/BL_Shin.STL" />
      </geometry>
      <material
        name="">
        <color
          rgba="0.792156862745098 0.819607843137255 0.933333333333333 1" />
      </material>
    </visual>
    <collision>
      <origin
        xyz="0 0 0"
        rpy="0 0 0" />
      <geometry>
        <mesh
          filename="package://Quad_Foot/meshes/BL_Shin.STL" />
      </geometry>
    </collision>
  </link>
  <joint
    name="BL_J3"
    type="continuous">
    <origin
      xyz="0 0 -0.318"
      rpy="0 0 0" />
    <parent
      link="BL_Thigh" />
    <child
      link="BL_Shin" />
    <axis
      xyz="1 0 0" />
  </joint>
  <link
    name="BL_Foot">
    <inertial>
      <origin
        xyz="-6.93889390390723E-18 0 0.00859640058408684"
        rpy="0 0 0" />
      <mass
        value="0.0212861829239045" />
      <inertia
        ixx="1.33702109373009E-06"
        ixy="-4.02969281675862E-21"
        ixz="1.03299645993047E-22"
        iyy="9.13522934420036E-06"
        iyz="-6.47619631205704E-22"
        izz="8.60215807525945E-06" />
    </inertial>
    <visual>
      <origin
        xyz="0 0 0"
        rpy="0 0 0" />
      <geometry>
        <mesh
          filename="package://Quad_Foot/meshes/BL_Foot.STL" />
      </geometry>
      <material
        name="">
        <color
          rgba="0.286274509803922 0.662745098039216 0.329411764705882 1" />
      </material>
    </visual>
    <collision>
      <origin
        xyz="0 0 0"
        rpy="0 0 0" />
      <geometry>
        <mesh
          filename="package://Quad_Foot/meshes/BL_Foot.STL" />
      </geometry>
    </collision>
  </link>
  <joint
    name="BL_J4"
    type="fixed">
    <origin
      xyz="-0.009 0 -0.3085"
      rpy="0 0 0" />
    <parent
      link="BL_Shin" />
    <child
      link="BL_Foot" />
    <axis
      xyz="0 0 0" />
  </joint>
</robot>